Workbook

Sheet Dashboard
A1: 📊 DASHBOARD KẾT QUẢ KINH DOANH Q2/2026
A2: Dữ liệu cập nhật tự động từ Sheet1 - Table1
A4: 📈 TỔNG SỐ DN | C4: 📊 ĐÃ CÔNG BỐ | F4: ✅ DN CÓ LÃI | H4: ❌ DN BỊ LỖ | J4: 📊 TỶ LỆ CÓ LÃI
A5: =COUNTA(INDEX(Sheet4!$A:$AG,0,_xlfn.XMATCH("Mã",Sheet4!$1:$1)))-1 -> 1593 | C5: {=_xlfn.LET( _xlpm.colDTT,_xlfn.XMATCH("*Doanh thu thuần*Q2*2026*",Sheet4!$1:$1,2), _xlpm.colTNL,_xlfn.XMATCH("*Thu nhập lãi thuần*Quý: 2*2026*",Sheet4!$1:$1,2), _xlpm.dttData,INDEX(Sheet4!$A:$AG,0,_xlpm.colDTT), _xlpm.tnlData,INDEX(Sheet4!$A:$AG,0,_xlpm.colTNL), SUMPRODUCT((_xlpm.dttData<>"")*(_xlpm.dttData<>0)*(ROW(_xlpm.dttData)>1)*1)+SUMPRODUCT((OR(_xlpm.dttData="",_xlpm.dttData=0))*(_xlpm.tnlData<>"")*(_xlpm.tnlData<>0)*(ROW(_xlpm.tnlData)>1)*1) )} -> 405 | F5: {=_xlfn.LET( _xlpm.colLNST,_xlfn.XMATCH("*Lợi nhuận sau thuế*Q2*2026*",Sheet4!$1:$1,2), _xlpm.lnstData,INDEX(Sheet4!$A:$AG,0,_xlpm.colLNST), SUMPRODUCT((_xlpm.lnstData>0)*(ROW(_xlpm.lnstData)>1)*1) )} -> 362 | H5: {=_xlfn.LET( _xlpm.colLNST,_xlfn.XMATCH("*Lợi nhuận sau thuế*Q2*2026*",Sheet4!$1:$1,2), _xlpm.lnstData,INDEX(Sheet4!$A:$AG,0,_xlpm.colLNST), SUMPRODUCT((_xlpm.lnstData<0)*(ROW(_xlpm.lnstData)>1)*1) )} -> 47 | J5: {=_xlfn.LET( _xlpm.colLNST,_xlfn.XMATCH("*Lợi nhuận sau thuế*Q2*2026*",Sheet4!$1:$1,2), _xlpm.lnstData,INDEX(Sheet4!$A:$AG,0,_xlpm.colLNST), _xlpm.coLai,SUMPRODUCT((_xlpm.lnstData>0)*(ROW(_xlpm.lnstData)>1)*1), _xlpm.biLo,SUMPRODUCT((_xlpm.lnstData<0)*(ROW(_xlpm.lnstData)>1)*1), _xlpm.coLai/(_xlpm.coLai+_xlpm.biLo) )} -> 0.88508557
A7: 📊 THỐNG KÊ THEO PHÂN NGÀNH (ICB L1)
A8: Phân ngành | B8: Số DN | C8: Đã công bố | D8: Tổng DT Q2 (tỷ) | E8: Tổng LNST Q2 (tỷ) | F8: DT (YoY %) | G8: LNST (YoY %)
A9: Công nghiệp | B9: =_xlfn.LET( _xlpm.colNganh,_xlfn.XMATCH("*ICB L1*",Sheet4!$1:$1,2), _xlpm.nganhData,INDEX(Sheet4!$2:$1605,0,_xlpm.colNganh), COUNTIF(_xlpm.nganhData,$A9) ) -> 572 | C9: {=_xlfn.LET( _xlpm.colNganh,_xlfn.XMATCH("*ICB L1*",Sheet4!$1:$1,2), _xlpm.colDTT,_xlfn.XMATCH("*Doanh thu thuần*Q2*2026*",Sheet4!$1:$1,2), _xlpm.colTNL,_xlfn.XMATCH("*Thu nhập lãi thuần*Quý: 2*2026*",Sheet4!$1:$1,2), _xlpm.nganhData,INDEX(Sheet4!$2:$1605,0,_xlpm.colNganh), _xlpm.dttData,INDEX(Sheet4!$2:$1605,0,_xlpm.colDTT), _xlpm.tnlData,INDEX(Sheet4!$2:$1605,0,_xlpm.colTNL), IF($A9="Ngân hàng", SUMPRODUCT((_xlpm.nganhData=$A9)*(_xlpm.tnlData<>"")*(_xlpm.tnlData<>0)*1), SUMPRODUCT((_xlpm.nganhData=$A9)*(_xlpm.dttData<>"")*(_xlpm.dttData<>0)*1) ) )} -> 114 | D9: {=_xlfn.LET( _xlpm.colNganh,_xlfn.XMATCH("*ICB L1*",Sheet4!$1:$1,2), _xlpm.colDTT,_xlfn.XMATCH("*Doanh thu thuần*Q2*2026*",Sheet4!$1:$1,2), _xlpm.colTNL,_xlfn.XMATCH("*Thu nhập lãi thuần*Quý: 2*2026*",Sheet4!$1:$1,2), _xlpm.nganhData,INDEX(Sheet4!$2:$1605,0,_xlpm.colNganh), _xlpm.dttData,INDEX(Sheet4!$2:$1605,0,_xlpm.colDTT), _xlpm.tnlData,INDEX(Sheet4!$2:$1605,0,_xlpm.colTNL), IF($A9="Ngân hàng", SUMPRODUCT((_xlpm.nganhData=$A9)*(_xlpm.tnlData))/1000000000, SUMPRODUCT((_xlpm.nganhData=$A9)*(_xlpm.dttData))/1000000000 ) )} -> 33929.182 | E9: {=_xlfn.LET( _xlpm.colNganh,_xlfn.XMATCH("*ICB L1*",Sheet4!$1:$1,2), _xlpm.colLNST,_xlfn.XMATCH("*Lợi nhuận sau thuế*Q2*2026*",Sheet4!$1:$1,2), _xlpm.nganhData,INDEX(Sheet4!$2:$1605,0,_xlpm.colNganh), _xlpm.lnstData,INDEX(Sheet4!$2:$1605,0,_xlpm.colLNST), SUMPRODUCT((_xlpm.nganhData=$A9)*(_xlpm.lnstData))/1000000000 )} -> 3439.4574 | F9: {=_xlfn.LET( _xlpm.colNganh,_xlfn.XMATCH("*ICB L1*",Sheet4!$1:$1,2), _xlpm.colDTT,_xlfn.XMATCH("*Doanh thu thuần*Q2*2026*",Sheet4!$1:$1,2), _xlpm.colTNL26,_xlfn.XMATCH("*Thu nhập lãi thuần*Quý: 2*2026*",Sheet4!$1:$1,2), _xlpm.colTNL25,_xlfn.XMATCH("*Thu nhập lãi thuần*Q2*2025*",Sheet4!$1:$1,2), _xlpm.colTTDTT,_xlfn.XMATCH("*Tăng trưởng doanh thu thuần (YoY) (Quý*",Sheet4!$1:$1,2), _xlpm.nganhData,INDEX(Sheet4!$2:$1605,0,_xlpm.colNganh), _xlpm.dttData,INDEX(Sheet4!$2:$1605,0,_xlpm.colDTT), _xlpm.tnl26Data,INDEX(Sheet4!$2:$1605,0,_xlpm.colTNL26), _xlpm.tnl25Data,INDEX(Sheet4!$2:$1605,0,_xlpm.colTNL25), _xlpm.ttdttData,INDEX(Sheet4!$2:$1605,0,_xlpm.colTTDTT), IF($A9="Ngân hàng", _xlfn.LET( _xlpm.sumTNL26,SUMPRODUCT((_xlpm.nganhData=$A9)*(_xlpm.tnl26Data<>0)*(_xlpm.tnl26Data)), _xlpm.sumTNL25Match,SUMPRODUCT((_xlpm.nganhData=$A9)*(_xlpm.tnl26Data<>0)*(_xlpm.tnl25Data)), IF(OR(_xlpm.sumTNL26=0,_xlpm.sumTNL25Match=0),"-",_xlpm.sumTNL26/_xlpm.sumTNL25Match-1) ), _xlfn.LET( _xlpm.tongDT,SUMPRODUCT((_xlpm.nganhData=$A9)*(_xlpm.dttData)), _xlpm.tongTT,SUMPRODUCT((_xlpm.nganhData=$A9)*(_xlpm.dttData)*(_xlpm.ttdttData)), IF(_xlpm.tongDT=0,"-",_xlpm.tongTT/_xlpm.tongDT) ) ) )} -> 0.33255605 | G9: {=_xlfn.LET( _xlpm.colNganh,_xlfn.XMATCH("*ICB L1*",Sheet4!$1:$1,2), _xlpm.colLNST,_xlfn.XMATCH("*Lợi nhuận sau thuế*Q2*2026*",Sheet4!$1:$1,2), _xlpm.colTTLNST,_xlfn.XMATCH("*Tăng trưởng lợi nhuận sau thuế (YoY) (Quý*",Sheet4!$1:$1,2), _xlpm.nganhData,INDEX(Sheet4!$2:$1605,0,_xlpm.colNganh), _xlpm.lnstData,INDEX(Sheet4!$2:$1605,0,_xlpm.colLNST), _xlpm.ttlnstData,INDEX(Sheet4!$2:$1605,0,_xlpm.colTTLNST), _xlfn.LET( _xlpm.tongLNST,SUMPRODUCT((_xlpm.nganhData=$A9)*(_xlpm.lnstData)), _xlpm.tongTT,SUMPRODUCT((_xlpm.nganhData=$A9)*(_xlpm.lnstData)*(_xlpm.ttlnstData)), IF(_xlpm.tongLNST=0,"-",_xlpm.tongTT/_xlpm.tongLNST) ) )} -> 3.9424359
A10: Công nghệ Thông tin | B10: =_xlfn.LET( _xlpm.colNganh,_xlfn.XMATCH("*ICB L1*",Sheet4!$1:$1,2), _xlpm.nganhData,INDEX(Sheet4!$2:$1605,0,_xlpm.colNganh), COUNTIF(_xlpm.nganhData,$A10) ) -> 27 | C10: {=_xlfn.LET( _xlpm.colNganh,_xlfn.XMATCH("*ICB L1*",Sheet4!$1:$1,2), _xlpm.colDTT,_xlfn.XMATCH("*Doanh thu thuần*Q2*2026*",Sheet4!$1:$1,2), _xlpm.colTNL,_xlfn.XMATCH("*Thu nhập lãi thuần*Quý: 2*2026*",Sheet4!$1:$1,2), _xlpm.nganhData,INDEX(Sheet4!$2:$1605,0,_xlpm.colNganh), _xlpm.dttData,INDEX(Sheet4!$2:$1605,0,_xlpm.colDTT), _xlpm.tnlData,INDEX(Sheet4!$2:$1605,0,_xlpm.colTNL), IF($A10="Ngân hàng", SUMPRODUCT((_xlpm.nganhData=$A10)*(_xlpm.tnlData<>"")*(_xlpm.tnlData<>0)*1), SUMPRODUCT((_xlpm.nganhData=$A10)*(_xlpm.dttData<>"")*(_xlpm.dttData<>0)*1) ) )} -> 4 | D10: {=_xlfn.LET( _xlpm.colNganh,_xlfn.XMATCH("*ICB L1*",Sheet4!$1:$1,2), _xlpm.colDTT,_xlfn.XMATCH("*Doanh thu thuần*Q2*2026*",Sheet4!$1:$1,2), _xlpm.colTNL,_xlfn.XMATCH("*Thu nhập lãi thuần*Quý: 2*2026*",Sheet4!$1:$1,2), _xlpm.nganhData,INDEX(Sheet4!$2:$1605,0,_xlpm.colNganh), _xlpm.dttData,INDEX(Sheet4!$2:$1605,0,_xlpm.colDTT), _xlpm.tnlData,INDEX(Sheet4!$2:$1605,0,_xlpm.colTNL), IF($A10="Ngân hàng", SUMPRODUCT((_xlpm.nganhData=$A10)*(_xlpm.tnlData))/1000000000, SUMPRODUCT((_xlpm.nganhData=$A10)*(_xlpm.dttData))/1000000000 ) )} -> 230.21316 | E10: {=_xlfn.LET( _xlpm.colNganh,_xlfn.XMATCH("*ICB L1*",Sheet4!$1:$1,2), _xlpm.colLNST,_xlfn.XMATCH("*Lợi nhuận sau thuế*Q2*2026*",Sheet4!$1:$1,2), _xlpm.nganhData,INDEX(Sheet4!$2:$1605,0,_xlpm.colNganh), _xlpm.lnstData,INDEX(Sheet4!$2:$1605,0,_xlpm.colLNST), SUMPRODUCT((_xlpm.nganhData=$A10)*(_xlpm.lnstData))/1000000000 )} -> 15.117617 | F10: {=_xlfn.LET( _xlpm.colNganh,_xlfn.XMATCH("*ICB L1*",Sheet4!$1:$1,2), _xlpm.colDTT,_xlfn.XMATCH("*Doanh thu thuần*Q2*2026*",Sheet4!$1:$1,2), _xlpm.colTNL26,_xlfn.XMATCH("*Thu nhập lãi thuần*Quý: 2*2026*",Sheet4!$1:$1,2), _xlpm.colTNL25,_xlfn.XMATCH("*Thu nhập lãi thuần*Q2*2025*",Sheet4!$1:$1,2), _xlpm.colTTDTT,_xlfn.XMATCH("*Tăng trưởng doanh thu thuần (YoY) (Quý*",Sheet4!$1:$1,2), _xlpm.nganhData,INDEX(Sheet4!$2:$1605,0,_xlpm.colNganh), _xlpm.dttData,INDEX(Sheet4!$2:$1605,0,_xlpm.colDTT), _xlpm.tnl26Data,INDEX(Sheet4!$2:$1605,0,_xlpm.colTNL26), _xlpm.tnl25Data,INDEX(Sheet4!$2:$1605,0,_xlpm.colTNL25), _xlpm.ttdttData,INDEX(Sheet4!$2:$1605,0,_xlpm.colTTDTT), IF($A10="Ngân hàng", _xlfn.LET( _xlpm.sumTNL26,SUMPRODUCT((_xlpm.nganhData=$A10)*(_xlpm.tnl26Data<>0)*(_xlpm.tnl26Data)), _xlpm.sumTNL25Match,SUMPRODUCT((_xlpm.nganhData=$A10)*(_xlpm.tnl26Data<>0)*(_xlpm.tnl25Data)), IF(OR(_xlpm.sumTNL26=0,_xlpm.sumTNL25Match=0),"-",_xlpm.sumTNL26/_xlpm.sumTNL25Match-1) ), _xlfn.LET( _xlpm.tongDT,SUMPRODUCT((_xlpm.nganhData=$A10)*(_xlpm.dttData)), _xlpm.tongTT,SUMPRODUCT((_xlpm.nganhData=$A10)*(_xlpm.dttData)*(_xlpm.ttdttData)), IF(_xlpm.tongDT=0,"-",_xlpm.tongTT/_xlpm.tongDT) ) ) )} -> 1.0373207 | G10: {=_xlfn.LET( _xlpm.colNganh,_xlfn.XMATCH("*ICB L1*",Sheet4!$1:$1,2), _xlpm.colLNST,_xlfn.XMATCH("*Lợi nhuận sau thuế*Q2*2026*",Sheet4!$1:$1,2), _xlpm.colTTLNST,_xlfn.XMATCH("*Tăng trưởng lợi nhuận sau thuế (YoY) (Quý*",Sheet4!$1:$1,2), _xlpm.nganhData,INDEX(Sheet4!$2:$1605,0,_xlpm.colNganh), _xlpm.lnstData,INDEX(Sheet4!$2:$1605,0,_xlpm.colLNST), _xlpm.ttlnstData,INDEX(Sheet4!$2:$1605,0,_xlpm.colTTLNST), _xlfn.LET( _xlpm.tongLNST,SUMPRODUCT((_xlpm.nganhData=$A10)*(_xlpm.lnstData)), _xlpm.tongTT,SUMPRODUCT((_xlpm.nganhData=$A10)*(_xlpm.lnstData)*(_xlpm.ttlnstData)), IF(_xlpm.tongLNST=0,"-",_xlpm.tongTT/_xlpm.tongLNST) ) )} -> 13.232936
A11: Dược phẩm và Y tế | B11: =_xlfn.LET( _xlpm.colNganh,_xlfn.XMATCH("*ICB L1*",Sheet4!$1:$1,2), _xlpm.nganhData,INDEX(Sheet4!$2:$1605,0,_xlpm.colNganh), COUNTIF(_xlpm.nganhData,$A11) ) -> 65 | C11: {=_xlfn.LET( _xlpm.colNganh,_xlfn.XMATCH("*ICB L1*",Sheet4!$1:$1,2), _xlpm.colDTT,_xlfn.XMATCH("*Doanh thu thuần*Q2*2026*",Sheet4!$1:$1,2), _xlpm.colTNL,_xlfn.XMATCH("*Thu nhập lãi thuần*Quý: 2*2026*",Sheet4!$1:$1,2), _xlpm.nganhData,INDEX(Sheet4!$2:$1605,0,_xlpm.colNganh), _xlpm.dttData,INDEX(Sheet4!$2:$1605,0,_xlpm.colDTT), _xlpm.tnlData,INDEX(Sheet4!$2:$1605,0,_xlpm.colTNL), IF($A11="Ngân hàng", SUMPRODUCT((_xlpm.nganhData=$A11)*(_xlpm.tnlData<>"")*(_xlpm.tnlData<>0)*1), SUMPRODUCT((_xlpm.nganhData=$A11)*(_xlpm.dttData<>"")*(_xlpm.dttData<>0)*1) ) )} -> 15 | D11: {=_xlfn.LET( _xlpm.colNganh,_xlfn.XMATCH("*ICB L1*",Sheet4!$1:$1,2), _xlpm.colDTT,_xlfn.XMATCH("*Doanh thu thuần*Q2*2026*",Sheet4!$1:$1,2), _xlpm.colTNL,_xlfn.XMATCH("*Thu nhập lãi thuần*Quý: 2*2026*",Sheet4!$1:$1,2), _xlpm.nganhData,INDEX(Sheet4!$2:$1605,0,_xlpm.colNganh), _xlpm.dttData,INDEX(Sheet4!$2:$1605,0,_xlpm.colDTT), _xlpm.tnlData,INDEX(Sheet4!$2:$1605,0,_xlpm.colTNL), IF($A11="Ngân hàng", SUMPRODUCT((_xlpm.nganhData=$A11)*(_xlpm.tnlData))/1000000000, SUMPRODUCT((_xlpm.nganhData=$A11)*(_xlpm.dttData))/1000000000 ) )} -> 4197.1007 | E11: {=_xlfn.LET( _xlpm.colNganh,_xlfn.XMATCH("*ICB L1*",Sheet4!$1:$1,2), _xlpm.colLNST,_xlfn.XMATCH("*Lợi nhuận sau thuế*Q2*2026*",Sheet4!$1:$1,2), _xlpm.nganhData,INDEX(Sheet4!$2:$1605,0,_xlpm.colNganh), _xlpm.lnstData,INDEX(Sheet4!$2:$1605,0,_xlpm.colLNST), SUMPRODUCT((_xlpm.nganhData=$A11)*(_xlpm.lnstData))/1000000000 )} -> 546.57342 | F11: {=_xlfn.LET( _xlpm.colNganh,_xlfn.XMATCH("*ICB L1*",Sheet4!$1:$1,2), _xlpm.colDTT,_xlfn.XMATCH("*Doanh thu thuần*Q2*2026*",Sheet4!$1:$1,2), _xlpm.colTNL26,_xlfn.XMATCH("*Thu nhập lãi thuần*Quý: 2*2026*",Sheet4!$1:$1,2), _xlpm.colTNL25,_xlfn.XMATCH("*Thu nhập lãi thuần*Q2*2025*",Sheet4!$1:$1,2), _xlpm.colTTDTT,_xlfn.XMATCH("*Tăng trưởng doanh thu thuần (YoY) (Quý*",Sheet4!$1:$1,2), _xlpm.nganhData,INDEX(Sheet4!$2:$1605,0,_xlpm.colNganh), _xlpm.dttData,INDEX(Sheet4!$2:$1605,0,_xlpm.colDTT), _xlpm.tnl26Data,INDEX(Sheet4!$2:$1605,0,_xlpm.colTNL26), _xlpm.tnl25Data,INDEX(Sheet4!$2:$1605,0,_xlpm.colTNL25), _xlpm.ttdttData,INDEX(Sheet4!$2:$1605,0,_xlpm.colTTDTT), IF($A11="Ngân hàng", _xlfn.LET( _xlpm.sumTNL26,SUMPRODUCT((_xlpm.nganhData=$A11)*(_xlpm.tnl26Data<>0)*(_xlpm.tnl26Data)), _xlpm.sumTNL25Match,SUMPRODUCT((_xlpm.nganhData=$A11)*(_xlpm.tnl26Data<>0)*(_xlpm.tnl25Data)), IF(OR(_xlpm.sumTNL26=0,_xlpm.sumTNL25Match=0),"-",_xlpm.sumTNL26/_xlpm.sumTNL25Match-1) ), _xlfn.LET( _xlpm.tongDT,SUMPRODUCT((_xlpm.nganhData=$A11)*(_xlpm.dttData)), _xlpm.tongTT,SUMPRODUCT((_xlpm.nganhData=$A11)*(_xlpm.dttData)*(_xlpm.ttdttData)), IF(_xlpm.tongDT=0,"-",_xlpm.tongTT/_xlpm.tongDT) ) ) )} -> 0.081299108 | G11: {=_xlfn.LET( _xlpm.colNganh,_xlfn.XMATCH("*ICB L1*",Sheet4!$1:$1,2), _xlpm.colLNST,_xlfn.XMATCH("*Lợi nhuận sau thuế*Q2*2026*",Sheet4!$1:$1,2), _xlpm.colTTLNST,_xlfn.XMATCH("*Tăng trưởng lợi nhuận sau thuế (YoY) (Quý*",Sheet4!$1:$1,2), _xlpm.nganhData,INDEX(Sheet4!$2:$1605,0,_xlpm.colNganh), _xlpm.lnstData,INDEX(Sheet4!$2:$1605,0,_xlpm.colLNST), _xlpm.ttlnstData,INDEX(Sheet4!$2:$1605,0,_xlpm.colTTLNST), _xlfn.LET( _xlpm.tongLNST,SUMPRODUCT((_xlpm.nganhData=$A11)*(_xlpm.lnstData)), _xlpm.tongTT,SUMPRODUCT((_xlpm.nganhData=$A11)*(_xlpm.lnstData)*(_xlpm.ttlnstData)), IF(_xlpm.tongLNST=0,"-",_xlpm.tongTT/_xlpm.tongLNST) ) )} -> 2.895358
A12: Dầu khí | B12: =_xlfn.LET( _xlpm.colNganh,_xlfn.XMATCH("*ICB L1*",Sheet4!$1:$1,2), _xlpm.nganhData,INDEX(Sheet4!$2:$1605,0,_xlpm.colNganh), COUNTIF(_xlpm.nganhData,$A12) ) -> 12 | C12: {=_xlfn.LET( _xlpm.colNganh,_xlfn.XMATCH("*ICB L1*",Sheet4!$1:$1,2), _xlpm.colDTT,_xlfn.XMATCH("*Doanh thu thuần*Q2*2026*",Sheet4!$1:$1,2), _xlpm.colTNL,_xlfn.XMATCH("*Thu nhập lãi thuần*Quý: 2*2026*",Sheet4!$1:$1,2), _xlpm.nganhData,INDEX(Sheet4!$2:$1605,0,_xlpm.colNganh), _xlpm.dttData,INDEX(Sheet4!$2:$1605,0,_xlpm.colDTT), _xlpm.tnlData,INDEX(Sheet4!$2:$1605,0,_xlpm.colTNL), IF($A12="Ngân hàng", SUMPRODUCT((_xlpm.nganhData=$A12)*(_xlpm.tnlData<>"")*(_xlpm.tnlData<>0)*1), SUMPRODUCT((_xlpm.nganhData=$A12)*(_xlpm.dttData<>"")*(_xlpm.dttData<>0)*1) ) )} -> 1 | D12: {=_xlfn.LET( _xlpm.colNganh,_xlfn.XMATCH("*ICB L1*",Sheet4!$1:$1,2), _xlpm.colDTT,_xlfn.XMATCH("*Doanh thu thuần*Q2*2026*",Sheet4!$1:$1,2), _xlpm.colTNL,_xlfn.XMATCH("*Thu nhập lãi thuần*Quý: 2*2026*",Sheet4!$1:$1,2), _xlpm.nganhData,INDEX(Sheet4!$2:$1605,0,_xlpm.colNganh), _xlpm.dttData,INDEX(Sheet4!$2:$1605,0,_xlpm.colDTT), _xlpm.tnlData,INDEX(Sheet4!$2:$1605,0,_xlpm.colTNL), IF($A12="Ngân hàng", SUMPRODUCT((_xlpm.nganhData=$A12)*(_xlpm.tnlData))/1000000000, SUMPRODUCT((_xlpm.nganhData=$A12)*(_xlpm.dttData))/1000000000 ) )} -> 1643.9066 | E12: {=_xlfn.LET( _xlpm.colNganh,_xlfn.XMATCH("*ICB L1*",Sheet4!$1:$1,2), _xlpm.colLNST,_xlfn.XMATCH("*Lợi nhuận sau thuế*Q2*2026*",Sheet4!$1:$1,2), _xlpm.nganhData,INDEX(Sheet4!$2:$1605,0,_xlpm.colNganh), _xlpm.lnstData,INDEX(Sheet4!$2:$1605,0,_xlpm.colLNST), SUMPRODUCT((_xlpm.nganhData=$A12)*(_xlpm.lnstData))/1000000000 )} -> 43.95777 | F12: {=_xlfn.LET( _xlpm.colNganh,_xlfn.XMATCH("*ICB L1*",Sheet4!$1:$1,2), _xlpm.colDTT,_xlfn.XMATCH("*Doanh thu thuần*Q2*2026*",Sheet4!$1:$1,2), _xlpm.colTNL26,_xlfn.XMATCH("*Thu nhập lãi thuần*Quý: 2*2026*",Sheet4!$1:$1,2), _xlpm.colTNL25,_xlfn.XMATCH("*Thu nhập lãi thuần*Q2*2025*",Sheet4!$1:$1,2), _xlpm.colTTDTT,_xlfn.XMATCH("*Tăng trưởng doanh thu thuần (YoY) (Quý*",Sheet4!$1:$1,2), _xlpm.nganhData,INDEX(Sheet4!$2:$1605,0,_xlpm.colNganh), _xlpm.dttData,INDEX(Sheet4!$2:$1605,0,_xlpm.colDTT), _xlpm.tnl26Data,INDEX(Sheet4!$2:$1605,0,_xlpm.colTNL26), _xlpm.tnl25Data,INDEX(Sheet4!$2:$1605,0,_xlpm.colTNL25), _xlpm.ttdttData,INDEX(Sheet4!$2:$1605,0,_xlpm.colTTDTT), IF($A12="Ngân hàng", _xlfn.LET( _xlpm.sumTNL26,SUMPRODUCT((_xlpm.nganhData=$A12)*(_xlpm.tnl26Data<>0)*(_xlpm.tnl26Data)), _xlpm.sumTNL25Match,SUMPRODUCT((_xlpm.nganhData=$A12)*(_xlpm.tnl26Data<>0)*(_xlpm.tnl25Data)), IF(OR(_xlpm.sumTNL26=0,_xlpm.sumTNL25Match=0),"-",_xlpm.sumTNL26/_xlpm.sumTNL25Match-1) ), _xlfn.LET( _xlpm.tongDT,SUMPRODUCT((_xlpm.nganhData=$A12)*(_xlpm.dttData)), _xlpm.tongTT,SUMPRODUCT((_xlpm.nganhData=$A12)*(_xlpm.dttData)*(_xlpm.ttdttData)), IF(_xlpm.tongDT=0,"-",_xlpm.tongTT/_xlpm.tongDT) ) ) )} -> 2.2415 | G12: {=_xlfn.LET( _xlpm.colNganh,_xlfn.XMATCH("*ICB L1*",Sheet4!$1:$1,2), _xlpm.colLNST,_xlfn.XMATCH("*Lợi nhuận sau thuế*Q2*2026*",Sheet4!$1:$1,2), _xlpm.colTTLNST,_xlfn.XMATCH("*Tăng trưởng lợi nhuận sau thuế (YoY) (Quý*",Sheet4!$1:$1,2), _xlpm.nganhData,INDEX(Sheet4!$2:$1605,0,_xlpm.colNganh), _xlpm.lnstData,INDEX(Sheet4!$2:$1605,0,_xlpm.colLNST), _xlpm.ttlnstData,INDEX(Sheet4!$2:$1605,0,_xlpm.colTTLNST), _xlfn.LET( _xlpm.tongLNST,SUMPRODUCT((_xlpm.nganhData=$A12)*(_xlpm.lnstData)), _xlpm.tongTT,SUMPRODUCT((_xlpm.nganhData=$A12)*(_xlpm.lnstData)*(_xlpm.ttlnstData)), IF(_xlpm.tongLNST=0,"-",_xlpm.tongTT/_xlpm.tongLNST) ) )} -> 1.3018
A13: Dịch vụ Tiêu dùng | B13: =_xlfn.LET( _xlpm.colNganh,_xlfn.XMATCH("*ICB L1*",Sheet4!$1:$1,2), _xlpm.nganhData,INDEX(Sheet4!$2:$1605,0,_xlpm.colNganh), COUNTIF(_xlpm.nganhData,$A13) ) -> 109 | C13: {=_xlfn.LET( _xlpm.colNganh,_xlfn.XMATCH("*ICB L1*",Sheet4!$1:$1,2), _xlpm.colDTT,_xlfn.XMATCH("*Doanh thu thuần*Q2*2026*",Sheet4!$1:$1,2), _xlpm.colTNL,_xlfn.XMATCH("*Thu nhập lãi thuần*Quý: 2*2026*",Sheet4!$1:$1,2), _xlpm.nganhData,INDEX(Sheet4!$2:$1605,0,_xlpm.colNganh), _xlpm.dttData,INDEX(Sheet4!$2:$1605,0,_xlpm.colDTT), _xlpm.tnlData,INDEX(Sheet4!$2:$1605,0,_xlpm.colTNL), IF($A13="Ngân hàng", SUMPRODUCT((_xlpm.nganhData=$A13)*(_xlpm.tnlData<>"")*(_xlpm.tnlData<>0)*1), SUMPRODUCT((_xlpm.nganhData=$A13)*(_xlpm.dttData<>"")*(_xlpm.dttData<>0)*1) ) )} -> 28 | D13: {=_xlfn.LET( _xlpm.colNganh,_xlfn.XMATCH("*ICB L1*",Sheet4!$1:$1,2), _xlpm.colDTT,_xlfn.XMATCH("*Doanh thu thuần*Q2*2026*",Sheet4!$1:$1,2), _xlpm.colTNL,_xlfn.XMATCH("*Thu nhập lãi thuần*Quý: 2*2026*",Sheet4!$1:$1,2), _xlpm.nganhData,INDEX(Sheet4!$2:$1605,0,_xlpm.colNganh), _xlpm.dttData,INDEX(Sheet4!$2:$1605,0,_xlpm.colDTT), _xlpm.tnlData,INDEX(Sheet4!$2:$1605,0,_xlpm.colTNL), IF($A13="Ngân hàng", SUMPRODUCT((_xlpm.nganhData=$A13)*(_xlpm.tnlData))/1000000000, SUMPRODUCT((_xlpm.nganhData=$A13)*(_xlpm.dttData))/1000000000 ) )} -> 10082.863 | E13: {=_xlfn.LET( _xlpm.colNganh,_xlfn.XMATCH("*ICB L1*",Sheet4!$1:$1,2), _xlpm.colLNST,_xlfn.XMATCH("*Lợi nhuận sau thuế*Q2*2026*",Sheet4!$1:$1,2), _xlpm.nganhData,INDEX(Sheet4!$2:$1605,0,_xlpm.colNganh), _xlpm.lnstData,INDEX(Sheet4!$2:$1605,0,_xlpm.colLNST), SUMPRODUCT((_xlpm.nganhData=$A13)*(_xlpm.lnstData))/1000000000 )} -> 809.50332 | F13: {=_xlfn.LET( _xlpm.colNganh,_xlfn.XMATCH("*ICB L1*",Sheet4!$1:$1,2), _xlpm.colDTT,_xlfn.XMATCH("*Doanh thu thuần*Q2*2026*",Sheet4!$1:$1,2), _xlpm.colTNL26,_xlfn.XMATCH("*Thu nhập lãi thuần*Quý: 2*2026*",Sheet4!$1:$1,2), _xlpm.colTNL25,_xlfn.XMATCH("*Thu nhập lãi thuần*Q2*2025*",Sheet4!$1:$1,2), _xlpm.colTTDTT,_xlfn.XMATCH("*Tăng trưởng doanh thu thuần (YoY) (Quý*",Sheet4!$1:$1,2), _xlpm.nganhData,INDEX(Sheet4!$2:$1605,0,_xlpm.colNganh), _xlpm.dttData,INDEX(Sheet4!$2:$1605,0,_xlpm.colDTT), _xlpm.tnl26Data,INDEX(Sheet4!$2:$1605,0,_xlpm.colTNL26), _xlpm.tnl25Data,INDEX(Sheet4!$2:$1605,0,_xlpm.colTNL25), _xlpm.ttdttData,INDEX(Sheet4!$2:$1605,0,_xlpm.colTTDTT), IF($A13="Ngân hàng", _xlfn.LET( _xlpm.sumTNL26,SUMPRODUCT((_xlpm.nganhData=$A13)*(_xlpm.tnl26Data<>0)*(_xlpm.tnl26Data)), _xlpm.sumTNL25Match,SUMPRODUCT((_xlpm.nganhData=$A13)*(_xlpm.tnl26Data<>0)*(_xlpm.tnl25Data)), IF(OR(_xlpm.sumTNL26=0,_xlpm.sumTNL25Match=0),"-",_xlpm.sumTNL26/_xlpm.sumTNL25Match-1) ), _xlfn.LET( _xlpm.tongDT,SUMPRODUCT((_xlpm.nganhData=$A13)*(_xlpm.dttData)), _xlpm.tongTT,SUMPRODUCT((_xlpm.nganhData=$A13)*(_xlpm.dttData)*(_xlpm.ttdttData)), IF(_xlpm.tongDT=0,"-",_xlpm.tongTT/_xlpm.tongDT) ) ) )} -> 0.21850025 | G13: {=_xlfn.LET( _xlpm.colNganh,_xlfn.XMATCH("*ICB L1*",Sheet4!$1:$1,2), _xlpm.colLNST,_xlfn.XMATCH("*Lợi nhuận sau thuế*Q2*2026*",Sheet4!$1:$1,2), _xlpm.colTTLNST,_xlfn.XMATCH("*Tăng trưởng lợi nhuận sau thuế (YoY) (Quý*",Sheet4!$1:$1,2), _xlpm.nganhData,INDEX(Sheet4!$2:$1605,0,_xlpm.colNganh), _xlpm.lnstData,INDEX(Sheet4!$2:$1605,0,_xlpm.colLNST), _xlpm.ttlnstData,INDEX(Sheet4!$2:$1605,0,_xlpm.colTTLNST), _xlfn.LET( _xlpm.tongLNST,SUMPRODUCT((_xlpm.nganhData=$A13)*(_xlpm.lnstData)), _xlpm.tongTT,SUMPRODUCT((_xlpm.nganhData=$A13)*(_xlpm.lnstData)*(_xlpm.ttlnstData)), IF(_xlpm.tongLNST=0,"-",_xlpm.tongTT/_xlpm.tongLNST) ) )} -> 1.6463304
A14: Hàng Tiêu dùng | B14: =_xlfn.LET( _xlpm.colNganh,_xlfn.XMATCH("*ICB L1*",Sheet4!$1:$1,2), _xlpm.nganhData,INDEX(Sheet4!$2:$1605,0,_xlpm.colNganh), COUNTIF(_xlpm.nganhData,$A14) ) -> 241 | C14: {=_xlfn.LET( _xlpm.colNganh,_xlfn.XMATCH("*ICB L1*",Sheet4!$1:$1,2), _xlpm.colDTT,_xlfn.XMATCH("*Doanh thu thuần*Q2*2026*",Sheet4!$1:$1,2), _xlpm.colTNL,_xlfn.XMATCH("*Thu nhập lãi thuần*Quý: 2*2026*",Sheet4!$1:$1,2), _xlpm.nganhData,INDEX(Sheet4!$2:$1605,0,_xlpm.colNganh), _xlpm.dttData,INDEX(Sheet4!$2:$1605,0,_xlpm.colDTT), _xlpm.tnlData,INDEX(Sheet4!$2:$1605,0,_xlpm.colTNL), IF($A14="Ngân hàng", SUMPRODUCT((_xlpm.nganhData=$A14)*(_xlpm.tnlData<>"")*(_xlpm.tnlData<>0)*1), SUMPRODUCT((_xlpm.nganhData=$A14)*(_xlpm.dttData<>"")*(_xlpm.dttData<>0)*1) ) )} -> 54 | D14: {=_xlfn.LET( _xlpm.colNganh,_xlfn.XMATCH("*ICB L1*",Sheet4!$1:$1,2), _xlpm.colDTT,_xlfn.XMATCH("*Doanh thu thuần*Q2*2026*",Sheet4!$1:$1,2), _xlpm.colTNL,_xlfn.XMATCH("*Thu nhập lãi thuần*Quý: 2*2026*",Sheet4!$1:$1,2), _xlpm.nganhData,INDEX(Sheet4!$2:$1605,0,_xlpm.colNganh), _xlpm.dttData,INDEX(Sheet4!$2:$1605,0,_xlpm.colDTT), _xlpm.tnlData,INDEX(Sheet4!$2:$1605,0,_xlpm.colTNL), IF($A14="Ngân hàng", SUMPRODUCT((_xlpm.nganhData=$A14)*(_xlpm.tnlData))/1000000000, SUMPRODUCT((_xlpm.nganhData=$A14)*(_xlpm.dttData))/1000000000 ) )} -> 23873.363 | E14: {=_xlfn.LET( _xlpm.colNganh,_xlfn.XMATCH("*ICB L1*",Sheet4!$1:$1,2), _xlpm.colLNST,_xlfn.XMATCH("*Lợi nhuận sau thuế*Q2*2026*",Sheet4!$1:$1,2), _xlpm.nganhData,INDEX(Sheet4!$2:$1605,0,_xlpm.colNganh), _xlpm.lnstData,INDEX(Sheet4!$2:$1605,0,_xlpm.colLNST), SUMPRODUCT((_xlpm.nganhData=$A14)*(_xlpm.lnstData))/1000000000 )} -> 1453.7812 | F14: {=_xlfn.LET( _xlpm.colNganh,_xlfn.XMATCH("*ICB L1*",Sheet4!$1:$1,2), _xlpm.colDTT,_xlfn.XMATCH("*Doanh thu thuần*Q2*2026*",Sheet4!$1:$1,2), _xlpm.colTNL26,_xlfn.XMATCH("*Thu nhập lãi thuần*Quý: 2*2026*",Sheet4!$1:$1,2), _xlpm.colTNL25,_xlfn.XMATCH("*Thu nhập lãi thuần*Q2*2025*",Sheet4!$1:$1,2), _xlpm.colTTDTT,_xlfn.XMATCH("*Tăng trưởng doanh thu thuần (YoY) (Quý*",Sheet4!$1:$1,2), _xlpm.nganhData,INDEX(Sheet4!$2:$1605,0,_xlpm.colNganh), _xlpm.dttData,INDEX(Sheet4!$2:$1605,0,_xlpm.colDTT), _xlpm.tnl26Data,INDEX(Sheet4!$2:$1605,0,_xlpm.colTNL26), _xlpm.tnl25Data,INDEX(Sheet4!$2:$1605,0,_xlpm.colTNL25), _xlpm.ttdttData,INDEX(Sheet4!$2:$1605,0,_xlpm.colTTDTT), IF($A14="Ngân hàng", _xlfn.LET( _xlpm.sumTNL26,SUMPRODUCT((_xlpm.nganhData=$A14)*(_xlpm.tnl26Data<>0)*(_xlpm.tnl26Data)), _xlpm.sumTNL25Match,SUMPRODUCT((_xlpm.nganhData=$A14)*(_xlpm.tnl26Data<>0)*(_xlpm.tnl25Data)), IF(OR(_xlpm.sumTNL26=0,_xlpm.sumTNL25Match=0),"-",_xlpm.sumTNL26/_xlpm.sumTNL25Match-1) ), _xlfn.LET( _xlpm.tongDT,SUMPRODUCT((_xlpm.nganhData=$A14)*(_xlpm.dttData)), _xlpm.tongTT,SUMPRODUCT((_xlpm.nganhData=$A14)*(_xlpm.dttData)*(_xlpm.ttdttData)), IF(_xlpm.tongDT=0,"-",_xlpm.tongTT/_xlpm.tongDT) ) ) )} -> 0.086271282 | G14: {=_xlfn.LET( _xlpm.colNganh,_xlfn.XMATCH("*ICB L1*",Sheet4!$1:$1,2), _xlpm.colLNST,_xlfn.XMATCH("*Lợi nhuận sau thuế*Q2*2026*",Sheet4!$1:$1,2), _xlpm.colTTLNST,_xlfn.XMATCH("*Tăng trưởng lợi nhuận sau thuế (YoY) (Quý*",Sheet4!$1:$1,2), _xlpm.nganhData,INDEX(Sheet4!$2:$1605,0,_xlpm.colNganh), _xlpm.lnstData,INDEX(Sheet4!$2:$1605,0,_xlpm.colLNST), _xlpm.ttlnstData,INDEX(Sheet4!$2:$1605,0,_xlpm.colTTLNST), _xlfn.LET( _xlpm.tongLNST,SUMPRODUCT((_xlpm.nganhData=$A14)*(_xlpm.lnstData)), _xlpm.tongTT,SUMPRODUCT((_xlpm.nganhData=$A14)*(_xlpm.lnstData)*(_xlpm.ttlnstData)), IF(_xlpm.tongLNST=0,"-",_xlpm.tongTT/_xlpm.tongLNST) ) )} -> 1.5510906
A15: Nguyên vật liệu | B15: =_xlfn.LET( _xlpm.colNganh,_xlfn.XMATCH("*ICB L1*",Sheet4!$1:$1,2), _xlpm.nganhData,INDEX(Sheet4!$2:$1605,0,_xlpm.colNganh), COUNTIF(_xlpm.nganhData,$A15) ) -> 177 | C15: {=_xlfn.LET( _xlpm.colNganh,_xlfn.XMATCH("*ICB L1*",Sheet4!$1:$1,2), _xlpm.colDTT,_xlfn.XMATCH("*Doanh thu thuần*Q2*2026*",Sheet4!$1:$1,2), _xlpm.colTNL,_xlfn.XMATCH("*Thu nhập lãi thuần*Quý: 2*2026*",Sheet4!$1:$1,2), _xlpm.nganhData,INDEX(Sheet4!$2:$1605,0,_xlpm.colNganh), _xlpm.dttData,INDEX(Sheet4!$2:$1605,0,_xlpm.colDTT), _xlpm.tnlData,INDEX(Sheet4!$2:$1605,0,_xlpm.colTNL), IF($A15="Ngân hàng", SUMPRODUCT((_xlpm.nganhData=$A15)*(_xlpm.tnlData<>"")*(_xlpm.tnlData<>0)*1), SUMPRODUCT((_xlpm.nganhData=$A15)*(_xlpm.dttData<>"")*(_xlpm.dttData<>0)*1) ) )} -> 55 | D15: {=_xlfn.LET( _xlpm.colNganh,_xlfn.XMATCH("*ICB L1*",Sheet4!$1:$1,2), _xlpm.colDTT,_xlfn.XMATCH("*Doanh thu thuần*Q2*2026*",Sheet4!$1:$1,2), _xlpm.colTNL,_xlfn.XMATCH("*Thu nhập lãi thuần*Quý: 2*2026*",Sheet4!$1:$1,2), _xlpm.nganhData,INDEX(Sheet4!$2:$1605,0,_xlpm.colNganh), _xlpm.dttData,INDEX(Sheet4!$2:$1605,0,_xlpm.colDTT), _xlpm.tnlData,INDEX(Sheet4!$2:$1605,0,_xlpm.colTNL), IF($A15="Ngân hàng", SUMPRODUCT((_xlpm.nganhData=$A15)*(_xlpm.tnlData))/1000000000, SUMPRODUCT((_xlpm.nganhData=$A15)*(_xlpm.dttData))/1000000000 ) )} -> 33424.859 | E15: {=_xlfn.LET( _xlpm.colNganh,_xlfn.XMATCH("*ICB L1*",Sheet4!$1:$1,2), _xlpm.colLNST,_xlfn.XMATCH("*Lợi nhuận sau thuế*Q2*2026*",Sheet4!$1:$1,2), _xlpm.nganhData,INDEX(Sheet4!$2:$1605,0,_xlpm.colNganh), _xlpm.lnstData,INDEX(Sheet4!$2:$1605,0,_xlpm.colLNST), SUMPRODUCT((_xlpm.nganhData=$A15)*(_xlpm.lnstData))/1000000000 )} -> 1298.9606 | F15: {=_xlfn.LET( _xlpm.colNganh,_xlfn.XMATCH("*ICB L1*",Sheet4!$1:$1,2), _xlpm.colDTT,_xlfn.XMATCH("*Doanh thu thuần*Q2*2026*",Sheet4!$1:$1,2), _xlpm.colTNL26,_xlfn.XMATCH("*Thu nhập lãi thuần*Quý: 2*2026*",Sheet4!$1:$1,2), _xlpm.colTNL25,_xlfn.XMATCH("*Thu nhập lãi thuần*Q2*2025*",Sheet4!$1:$1,2), _xlpm.colTTDTT,_xlfn.XMATCH("*Tăng trưởng doanh thu thuần (YoY) (Quý*",Sheet4!$1:$1,2), _xlpm.nganhData,INDEX(Sheet4!$2:$1605,0,_xlpm.colNganh), _xlpm.dttData,INDEX(Sheet4!$2:$1605,0,_xlpm.colDTT), _xlpm.tnl26Data,INDEX(Sheet4!$2:$1605,0,_xlpm.colTNL26), _xlpm.tnl25Data,INDEX(Sheet4!$2:$1605,0,_xlpm.colTNL25), _xlpm.ttdttData,INDEX(Sheet4!$2:$1605,0,_xlpm.colTTDTT), IF($A15="Ngân hàng", _xlfn.LET( _xlpm.sumTNL26,SUMPRODUCT((_xlpm.nganhData=$A15)*(_xlpm.tnl26Data<>0)*(_xlpm.tnl26Data)), _xlpm.sumTNL25Match,SUMPRODUCT((_xlpm.nganhData=$A15)*(_xlpm.tnl26Data<>0)*(_xlpm.tnl25Data)), IF(OR(_xlpm.sumTNL26=0,_xlpm.sumTNL25Match=0),"-",_xlpm.sumTNL26/_xlpm.sumTNL25Match-1) ), _xlfn.LET( _xlpm.tongDT,SUMPRODUCT((_xlpm.nganhData=$A15)*(_xlpm.dttData)), _xlpm.tongTT,SUMPRODUCT((_xlpm.nganhData=$A15)*(_xlpm.dttData)*(_xlpm.ttdttData)), IF(_xlpm.tongDT=0,"-",_xlpm.tongTT/_xlpm.tongDT) ) ) )} -> 0.094879474 | G15: {=_xlfn.LET( _xlpm.colNganh,_xlfn.XMATCH("*ICB L1*",Sheet4!$1:$1,2), _xlpm.colLNST,_xlfn.XMATCH("*Lợi nhuận sau thuế*Q2*2026*",Sheet4!$1:$1,2), _xlpm.colTTLNST,_xlfn.XMATCH("*Tăng trưởng lợi nhuận sau thuế (YoY) (Quý*",Sheet4!$1:$1,2), _xlpm.nganhData,INDEX(Sheet4!$2:$1605,0,_xlpm.colNganh), _xlpm.lnstData,INDEX(Sheet4!$2:$1605,0,_xlpm.colLNST), _xlpm.ttlnstData,INDEX(Sheet4!$2:$1605,0,_xlpm.colTTLNST), _xlfn.LET( _xlpm.tongLNST,SUMPRODUCT((_xlpm.nganhData=$A15)*(_xlpm.lnstData)), _xlpm.tongTT,SUMPRODUCT((_xlpm.nganhData=$A15)*(_xlpm.lnstData)*(_xlpm.ttlnstData)), IF(_xlpm.tongLNST=0,"-",_xlpm.tongTT/_xlpm.tongLNST) ) )} -> 0.77945911
A16: Ngân hàng | B16: =_xlfn.LET( _xlpm.colNganh,_xlfn.XMATCH("*ICB L1*",Sheet4!$1:$1,2), _xlpm.nganhData,INDEX(Sheet4!$2:$1605,0,_xlpm.colNganh), COUNTIF(_xlpm.nganhData,$A16) ) -> 28 | C16: {=_xlfn.LET( _xlpm.colNganh,_xlfn.XMATCH("*ICB L1*",Sheet4!$1:$1,2), _xlpm.colDTT,_xlfn.XMATCH("*Doanh thu thuần*Q2*2026*",Sheet4!$1:$1,2), _xlpm.colTNL,_xlfn.XMATCH("*Thu nhập lãi thuần*Quý: 2*2026*",Sheet4!$1:$1,2), _xlpm.nganhData,INDEX(Sheet4!$2:$1605,0,_xlpm.colNganh), _xlpm.dttData,INDEX(Sheet4!$2:$1605,0,_xlpm.colDTT), _xlpm.tnlData,INDEX(Sheet4!$2:$1605,0,_xlpm.colTNL), IF($A16="Ngân hàng", SUMPRODUCT((_xlpm.nganhData=$A16)*(_xlpm.tnlData<>"")*(_xlpm.tnlData<>0)*1), SUMPRODUCT((_xlpm.nganhData=$A16)*(_xlpm.dttData<>"")*(_xlpm.dttData<>0)*1) ) )} -> 6 | D16: {=_xlfn.LET( _xlpm.colNganh,_xlfn.XMATCH("*ICB L1*",Sheet4!$1:$1,2), _xlpm.colDTT,_xlfn.XMATCH("*Doanh thu thuần*Q2*2026*",Sheet4!$1:$1,2), _xlpm.colTNL,_xlfn.XMATCH("*Thu nhập lãi thuần*Quý: 2*2026*",Sheet4!$1:$1,2), _xlpm.nganhData,INDEX(Sheet4!$2:$1605,0,_xlpm.colNganh), _xlpm.dttData,INDEX(Sheet4!$2:$1605,0,_xlpm.colDTT), _xlpm.tnlData,INDEX(Sheet4!$2:$1605,0,_xlpm.colTNL), IF($A16="Ngân hàng", SUMPRODUCT((_xlpm.nganhData=$A16)*(_xlpm.tnlData))/1000000000, SUMPRODUCT((_xlpm.nganhData=$A16)*(_xlpm.dttData))/1000000000 ) )} -> 41884.24 | E16: {=_xlfn.LET( _xlpm.colNganh,_xlfn.XMATCH("*ICB L1*",Sheet4!$1:$1,2), _xlpm.colLNST,_xlfn.XMATCH("*Lợi nhuận sau thuế*Q2*2026*",Sheet4!$1:$1,2), _xlpm.nganhData,INDEX(Sheet4!$2:$1605,0,_xlpm.colNganh), _xlpm.lnstData,INDEX(Sheet4!$2:$1605,0,_xlpm.colLNST), SUMPRODUCT((_xlpm.nganhData=$A16)*(_xlpm.lnstData))/1000000000 )} -> 23891.646 | F16: {=_xlfn.LET( _xlpm.colNganh,_xlfn.XMATCH("*ICB L1*",Sheet4!$1:$1,2), _xlpm.colDTT,_xlfn.XMATCH("*Doanh thu thuần*Q2*2026*",Sheet4!$1:$1,2), _xlpm.colTNL26,_xlfn.XMATCH("*Thu nhập lãi thuần*Quý: 2*2026*",Sheet4!$1:$1,2), _xlpm.colTNL25,_xlfn.XMATCH("*Thu nhập lãi thuần*Q2*2025*",Sheet4!$1:$1,2), _xlpm.colTTDTT,_xlfn.XMATCH("*Tăng trưởng doanh thu thuần (YoY) (Quý*",Sheet4!$1:$1,2), _xlpm.nganhData,INDEX(Sheet4!$2:$1605,0,_xlpm.colNganh), _xlpm.dttData,INDEX(Sheet4!$2:$1605,0,_xlpm.colDTT), _xlpm.tnl26Data,INDEX(Sheet4!$2:$1605,0,_xlpm.colTNL26), _xlpm.tnl25Data,INDEX(Sheet4!$2:$1605,0,_xlpm.colTNL25), _xlpm.ttdttData,INDEX(Sheet4!$2:$1605,0,_xlpm.colTTDTT), IF($A16="Ngân hàng", _xlfn.LET( _xlpm.sumTNL26,SUMPRODUCT((_xlpm.nganhData=$A16)*(_xlpm.tnl26Data<>0)*(_xlpm.tnl26Data)), _xlpm.sumTNL25Match,SUMPRODUCT((_xlpm.nganhData=$A16)*(_xlpm.tnl26Data<>0)*(_xlpm.tnl25Data)), IF(OR(_xlpm.sumTNL26=0,_xlpm.sumTNL25Match=0),"-",_xlpm.sumTNL26/_xlpm.sumTNL25Match-1) ), _xlfn.LET( _xlpm.tongDT,SUMPRODUCT((_xlpm.nganhData=$A16)*(_xlpm.dttData)), _xlpm.tongTT,SUMPRODUCT((_xlpm.nganhData=$A16)*(_xlpm.dttData)*(_xlpm.ttdttData)), IF(_xlpm.tongDT=0,"-",_xlpm.tongTT/_xlpm.tongDT) ) ) )} -> 0.19630757 | G16: {=_xlfn.LET( _xlpm.colNganh,_xlfn.XMATCH("*ICB L1*",Sheet4!$1:$1,2), _xlpm.colLNST,_xlfn.XMATCH("*Lợi nhuận sau thuế*Q2*2026*",Sheet4!$1:$1,2), _xlpm.colTTLNST,_xlfn.XMATCH("*Tăng trưởng lợi nhuận sau thuế (YoY) (Quý*",Sheet4!$1:$1,2), _xlpm.nganhData,INDEX(Sheet4!$2:$1605,0,_xlpm.colNganh), _xlpm.lnstData,INDEX(Sheet4!$2:$1605,0,_xlpm.colLNST), _xlpm.ttlnstData,INDEX(Sheet4!$2:$1605,0,_xlpm.colTTLNST), _xlfn.LET( _xlpm.tongLNST,SUMPRODUCT((_xlpm.nganhData=$A16)*(_xlpm.lnstData)), _xlpm.tongTT,SUMPRODUCT((_xlpm.nganhData=$A16)*(_xlpm.lnstData)*(_xlpm.ttlnstData)), IF(_xlpm.tongLNST=0,"-",_xlpm.tongTT/_xlpm.tongLNST) ) )} -> 0.31664278
A17: Tiện ích Cộng đồng | B17: =_xlfn.LET( _xlpm.colNganh,_xlfn.XMATCH("*ICB L1*",Sheet4!$1:$1,2), _xlpm.nganhData,INDEX(Sheet4!$2:$1605,0,_xlpm.colNganh), COUNTIF(_xlpm.nganhData,$A17) ) -> 141 | C17: {=_xlfn.LET( _xlpm.colNganh,_xlfn.XMATCH("*ICB L1*",Sheet4!$1:$1,2), _xlpm.colDTT,_xlfn.XMATCH("*Doanh thu thuần*Q2*2026*",Sheet4!$1:$1,2), _xlpm.colTNL,_xlfn.XMATCH("*Thu nhập lãi thuần*Quý: 2*2026*",Sheet4!$1:$1,2), _xlpm.nganhData,INDEX(Sheet4!$2:$1605,0,_xlpm.colNganh), _xlpm.dttData,INDEX(Sheet4!$2:$1605,0,_xlpm.colDTT), _xlpm.tnlData,INDEX(Sheet4!$2:$1605,0,_xlpm.colTNL), IF($A17="Ngân hàng", SUMPRODUCT((_xlpm.nganhData=$A17)*(_xlpm.tnlData<>"")*(_xlpm.tnlData<>0)*1), SUMPRODUCT((_xlpm.nganhData=$A17)*(_xlpm.dttData<>"")*(_xlpm.dttData<>0)*1) ) )} -> 57 | D17: {=_xlfn.LET( _xlpm.colNganh,_xlfn.XMATCH("*ICB L1*",Sheet4!$1:$1,2), _xlpm.colDTT,_xlfn.XMATCH("*Doanh thu thuần*Q2*2026*",Sheet4!$1:$1,2), _xlpm.colTNL,_xlfn.XMATCH("*Thu nhập lãi thuần*Quý: 2*2026*",Sheet4!$1:$1,2), _xlpm.nganhData,INDEX(Sheet4!$2:$1605,0,_xlpm.colNganh), _xlpm.dttData,INDEX(Sheet4!$2:$1605,0,_xlpm.colDTT), _xlpm.tnlData,INDEX(Sheet4!$2:$1605,0,_xlpm.colTNL), IF($A17="Ngân hàng", SUMPRODUCT((_xlpm.nganhData=$A17)*(_xlpm.tnlData))/1000000000, SUMPRODUCT((_xlpm.nganhData=$A17)*(_xlpm.dttData))/1000000000 ) )} -> 35300.077 | E17: {=_xlfn.LET( _xlpm.colNganh,_xlfn.XMATCH("*ICB L1*",Sheet4!$1:$1,2), _xlpm.colLNST,_xlfn.XMATCH("*Lợi nhuận sau thuế*Q2*2026*",Sheet4!$1:$1,2), _xlpm.nganhData,INDEX(Sheet4!$2:$1605,0,_xlpm.colNganh), _xlpm.lnstData,INDEX(Sheet4!$2:$1605,0,_xlpm.colLNST), SUMPRODUCT((_xlpm.nganhData=$A17)*(_xlpm.lnstData))/1000000000 )} -> 2034.3132 | F17: {=_xlfn.LET( _xlpm.colNganh,_xlfn.XMATCH("*ICB L1*",Sheet4!$1:$1,2), _xlpm.colDTT,_xlfn.XMATCH("*Doanh thu thuần*Q2*2026*",Sheet4!$1:$1,2), _xlpm.colTNL26,_xlfn.XMATCH("*Thu nhập lãi thuần*Quý: 2*2026*",Sheet4!$1:$1,2), _xlpm.colTNL25,_xlfn.XMATCH("*Thu nhập lãi thuần*Q2*2025*",Sheet4!$1:$1,2), _xlpm.colTTDTT,_xlfn.XMATCH("*Tăng trưởng doanh thu thuần (YoY) (Quý*",Sheet4!$1:$1,2), _xlpm.nganhData,INDEX(Sheet4!$2:$1605,0,_xlpm.colNganh), _xlpm.dttData,INDEX(Sheet4!$2:$1605,0,_xlpm.colDTT), _xlpm.tnl26Data,INDEX(Sheet4!$2:$1605,0,_xlpm.colTNL26), _xlpm.tnl25Data,INDEX(Sheet4!$2:$1605,0,_xlpm.colTNL25), _xlpm.ttdttData,INDEX(Sheet4!$2:$1605,0,_xlpm.colTTDTT), IF($A17="Ngân hàng", _xlfn.LET( _xlpm.sumTNL26,SUMPRODUCT((_xlpm.nganhData=$A17)*(_xlpm.tnl26Data<>0)*(_xlpm.tnl26Data)), _xlpm.sumTNL25Match,SUMPRODUCT((_xlpm.nganhData=$A17)*(_xlpm.tnl26Data<>0)*(_xlpm.tnl25Data)), IF(OR(_xlpm.sumTNL26=0,_xlpm.sumTNL25Match=0),"-",_xlpm.sumTNL26/_xlpm.sumTNL25Match-1) ), _xlfn.LET( _xlpm.tongDT,SUMPRODUCT((_xlpm.nganhData=$A17)*(_xlpm.dttData)), _xlpm.tongTT,SUMPRODUCT((_xlpm.nganhData=$A17)*(_xlpm.dttData)*(_xlpm.ttdttData)), IF(_xlpm.tongDT=0,"-",_xlpm.tongTT/_xlpm.tongDT) ) ) )} -> 0.38972356 | G17: {=_xlfn.LET( _xlpm.colNganh,_xlfn.XMATCH("*ICB L1*",Sheet4!$1:$1,2), _xlpm.colLNST,_xlfn.XMATCH("*Lợi nhuận sau thuế*Q2*2026*",Sheet4!$1:$1,2), _xlpm.colTTLNST,_xlfn.XMATCH("*Tăng trưởng lợi nhuận sau thuế (YoY) (Quý*",Sheet4!$1:$1,2), _xlpm.nganhData,INDEX(Sheet4!$2:$1605,0,_xlpm.colNganh), _xlpm.lnstData,INDEX(Sheet4!$2:$1605,0,_xlpm.colLNST), _xlpm.ttlnstData,INDEX(Sheet4!$2:$1605,0,_xlpm.colTTLNST), _xlfn.LET( _xlpm.tongLNST,SUMPRODUCT((_xlpm.nganhData=$A17)*(_xlpm.lnstData)), _xlpm.tongTT,SUMPRODUCT((_xlpm.nganhData=$A17)*(_xlpm.lnstData)*(_xlpm.ttlnstData)), IF(_xlpm.tongLNST=0,"-",_xlpm.tongTT/_xlpm.tongLNST) ) )} -> 0.92146668
A18: Tài chính | B18: =_xlfn.LET( _xlpm.colNganh,_xlfn.XMATCH("*ICB L1*",Sheet4!$1:$1,2), _xlpm.nganhData,INDEX(Sheet4!$2:$1605,0,_xlpm.colNganh), COUNTIF(_xlpm.nganhData,$A18) ) -> 213 | C18: {=_xlfn.LET( _xlpm.colNganh,_xlfn.XMATCH("*ICB L1*",Sheet4!$1:$1,2), _xlpm.colDTT,_xlfn.XMATCH("*Doanh thu thuần*Q2*2026*",Sheet4!$1:$1,2), _xlpm.colTNL,_xlfn.XMATCH("*Thu nhập lãi thuần*Quý: 2*2026*",Sheet4!$1:$1,2), _xlpm.nganhData,INDEX(Sheet4!$2:$1605,0,_xlpm.colNganh), _xlpm.dttData,INDEX(Sheet4!$2:$1605,0,_xlpm.colDTT), _xlpm.tnlData,INDEX(Sheet4!$2:$1605,0,_xlpm.colTNL), IF($A18="Ngân hàng", SUMPRODUCT((_xlpm.nganhData=$A18)*(_xlpm.tnlData<>"")*(_xlpm.tnlData<>0)*1), SUMPRODUCT((_xlpm.nganhData=$A18)*(_xlpm.dttData<>"")*(_xlpm.dttData<>0)*1) ) )} -> 69 | D18: {=_xlfn.LET( _xlpm.colNganh,_xlfn.XMATCH("*ICB L1*",Sheet4!$1:$1,2), _xlpm.colDTT,_xlfn.XMATCH("*Doanh thu thuần*Q2*2026*",Sheet4!$1:$1,2), _xlpm.colTNL,_xlfn.XMATCH("*Thu nhập lãi thuần*Quý: 2*2026*",Sheet4!$1:$1,2), _xlpm.nganhData,INDEX(Sheet4!$2:$1605,0,_xlpm.colNganh), _xlpm.dttData,INDEX(Sheet4!$2:$1605,0,_xlpm.colDTT), _xlpm.tnlData,INDEX(Sheet4!$2:$1605,0,_xlpm.colTNL), IF($A18="Ngân hàng", SUMPRODUCT((_xlpm.nganhData=$A18)*(_xlpm.tnlData))/1000000000, SUMPRODUCT((_xlpm.nganhData=$A18)*(_xlpm.dttData))/1000000000 ) )} -> 32092.385 | E18: {=_xlfn.LET( _xlpm.colNganh,_xlfn.XMATCH("*ICB L1*",Sheet4!$1:$1,2), _xlpm.colLNST,_xlfn.XMATCH("*Lợi nhuận sau thuế*Q2*2026*",Sheet4!$1:$1,2), _xlpm.nganhData,INDEX(Sheet4!$2:$1605,0,_xlpm.colNganh), _xlpm.lnstData,INDEX(Sheet4!$2:$1605,0,_xlpm.colLNST), SUMPRODUCT((_xlpm.nganhData=$A18)*(_xlpm.lnstData))/1000000000 )} -> 10492.285 | F18: {=_xlfn.LET( _xlpm.colNganh,_xlfn.XMATCH("*ICB L1*",Sheet4!$1:$1,2), _xlpm.colDTT,_xlfn.XMATCH("*Doanh thu thuần*Q2*2026*",Sheet4!$1:$1,2), _xlpm.colTNL26,_xlfn.XMATCH("*Thu nhập lãi thuần*Quý: 2*2026*",Sheet4!$1:$1,2), _xlpm.colTNL25,_xlfn.XMATCH("*Thu nhập lãi thuần*Q2*2025*",Sheet4!$1:$1,2), _xlpm.colTTDTT,_xlfn.XMATCH("*Tăng trưởng doanh thu thuần (YoY) (Quý*",Sheet4!$1:$1,2), _xlpm.nganhData,INDEX(Sheet4!$2:$1605,0,_xlpm.colNganh), _xlpm.dttData,INDEX(Sheet4!$2:$1605,0,_xlpm.colDTT), _xlpm.tnl26Data,INDEX(Sheet4!$2:$1605,0,_xlpm.colTNL26), _xlpm.tnl25Data,INDEX(Sheet4!$2:$1605,0,_xlpm.colTNL25), _xlpm.ttdttData,INDEX(Sheet4!$2:$1605,0,_xlpm.colTTDTT), IF($A18="Ngân hàng", _xlfn.LET( _xlpm.sumTNL26,SUMPRODUCT((_xlpm.nganhData=$A18)*(_xlpm.tnl26Data<>0)*(_xlpm.tnl26Data)), _xlpm.sumTNL25Match,SUMPRODUCT((_xlpm.nganhData=$A18)*(_xlpm.tnl26Data<>0)*(_xlpm.tnl25Data)), IF(OR(_xlpm.sumTNL26=0,_xlpm.sumTNL25Match=0),"-",_xlpm.sumTNL26/_xlpm.sumTNL25Match-1) ), _xlfn.LET( _xlpm.tongDT,SUMPRODUCT((_xlpm.nganhData=$A18)*(_xlpm.dttData)), _xlpm.tongTT,SUMPRODUCT((_xlpm.nganhData=$A18)*(_xlpm.dttData)*(_xlpm.ttdttData)), IF(_xlpm.tongDT=0,"-",_xlpm.tongTT/_xlpm.tongDT) ) ) )} -> 1.8165816 | G18: {=_xlfn.LET( _xlpm.colNganh,_xlfn.XMATCH("*ICB L1*",Sheet4!$1:$1,2), _xlpm.colLNST,_xlfn.XMATCH("*Lợi nhuận sau thuế*Q2*2026*",Sheet4!$1:$1,2), _xlpm.colTTLNST,_xlfn.XMATCH("*Tăng trưởng lợi nhuận sau thuế (YoY) (Quý*",Sheet4!$1:$1,2), _xlpm.nganhData,INDEX(Sheet4!$2:$1605,0,_xlpm.colNganh), _xlpm.lnstData,INDEX(Sheet4!$2:$1605,0,_xlpm.colLNST), _xlpm.ttlnstData,INDEX(Sheet4!$2:$1605,0,_xlpm.colTTLNST), _xlfn.LET( _xlpm.tongLNST,SUMPRODUCT((_xlpm.nganhData=$A18)*(_xlpm.lnstData)), _xlpm.tongTT,SUMPRODUCT((_xlpm.nganhData=$A18)*(_xlpm.lnstData)*(_xlpm.ttlnstData)), IF(_xlpm.tongLNST=0,"-",_xlpm.tongTT/_xlpm.tongLNST) ) )} -> 2.5227069
A19: Viễn thông | B19: =_xlfn.LET( _xlpm.colNganh,_xlfn.XMATCH("*ICB L1*",Sheet4!$1:$1,2), _xlpm.nganhData,INDEX(Sheet4!$2:$1605,0,_xlpm.colNganh), COUNTIF(_xlpm.nganhData,$A19) ) -> 8 | C19: {=_xlfn.LET( _xlpm.colNganh,_xlfn.XMATCH("*ICB L1*",Sheet4!$1:$1,2), _xlpm.colDTT,_xlfn.XMATCH("*Doanh thu thuần*Q2*2026*",Sheet4!$1:$1,2), _xlpm.colTNL,_xlfn.XMATCH("*Thu nhập lãi thuần*Quý: 2*2026*",Sheet4!$1:$1,2), _xlpm.nganhData,INDEX(Sheet4!$2:$1605,0,_xlpm.colNganh), _xlpm.dttData,INDEX(Sheet4!$2:$1605,0,_xlpm.colDTT), _xlpm.tnlData,INDEX(Sheet4!$2:$1605,0,_xlpm.colTNL), IF($A19="Ngân hàng", SUMPRODUCT((_xlpm.nganhData=$A19)*(_xlpm.tnlData<>"")*(_xlpm.tnlData<>0)*1), SUMPRODUCT((_xlpm.nganhData=$A19)*(_xlpm.dttData<>"")*(_xlpm.dttData<>0)*1) ) )} -> 0 | D19: {=_xlfn.LET( _xlpm.colNganh,_xlfn.XMATCH("*ICB L1*",Sheet4!$1:$1,2), _xlpm.colDTT,_xlfn.XMATCH("*Doanh thu thuần*Q2*2026*",Sheet4!$1:$1,2), _xlpm.colTNL,_xlfn.XMATCH("*Thu nhập lãi thuần*Quý: 2*2026*",Sheet4!$1:$1,2), _xlpm.nganhData,INDEX(Sheet4!$2:$1605,0,_xlpm.colNganh), _xlpm.dttData,INDEX(Sheet4!$2:$1605,0,_xlpm.colDTT), _xlpm.tnlData,INDEX(Sheet4!$2:$1605,0,_xlpm.colTNL), IF($A19="Ngân hàng", SUMPRODUCT((_xlpm.nganhData=$A19)*(_xlpm.tnlData))/1000000000, SUMPRODUCT((_xlpm.nganhData=$A19)*(_xlpm.dttData))/1000000000 ) )} -> 0 | E19: {=_xlfn.LET( _xlpm.colNganh,_xlfn.XMATCH("*ICB L1*",Sheet4!$1:$1,2), _xlpm.colLNST,_xlfn.XMATCH("*Lợi nhuận sau thuế*Q2*2026*",Sheet4!$1:$1,2), _xlpm.nganhData,INDEX(Sheet4!$2:$1605,0,_xlpm.colNganh), _xlpm.lnstData,INDEX(Sheet4!$2:$1605,0,_xlpm.colLNST), SUMPRODUCT((_xlpm.nganhData=$A19)*(_xlpm.lnstData))/1000000000 )} -> 0 | F19: {=_xlfn.LET( _xlpm.colNganh,_xlfn.XMATCH("*ICB L1*",Sheet4!$1:$1,2), _xlpm.colDTT,_xlfn.XMATCH("*Doanh thu thuần*Q2*2026*",Sheet4!$1:$1,2), _xlpm.colTNL26,_xlfn.XMATCH("*Thu nhập lãi thuần*Quý: 2*2026*",Sheet4!$1:$1,2), _xlpm.colTNL25,_xlfn.XMATCH("*Thu nhập lãi thuần*Q2*2025*",Sheet4!$1:$1,2), _xlpm.colTTDTT,_xlfn.XMATCH("*Tăng trưởng doanh thu thuần (YoY) (Quý*",Sheet4!$1:$1,2), _xlpm.nganhData,INDEX(Sheet4!$2:$1605,0,_xlpm.colNganh), _xlpm.dttData,INDEX(Sheet4!$2:$1605,0,_xlpm.colDTT), _xlpm.tnl26Data,INDEX(Sheet4!$2:$1605,0,_xlpm.colTNL26), _xlpm.tnl25Data,INDEX(Sheet4!$2:$1605,0,_xlpm.colTNL25), _xlpm.ttdttData,INDEX(Sheet4!$2:$1605,0,_xlpm.colTTDTT), IF($A19="Ngân hàng", _xlfn.LET( _xlpm.sumTNL26,SUMPRODUCT((_xlpm.nganhData=$A19)*(_xlpm.tnl26Data<>0)*(_xlpm.tnl26Data)), _xlpm.sumTNL25Match,SUMPRODUCT((_xlpm.nganhData=$A19)*(_xlpm.tnl26Data<>0)*(_xlpm.tnl25Data)), IF(OR(_xlpm.sumTNL26=0,_xlpm.sumTNL25Match=0),"-",_xlpm.sumTNL26/_xlpm.sumTNL25Match-1) ), _xlfn.LET( _xlpm.tongDT,SUMPRODUCT((_xlpm.nganhData=$A19)*(_xlpm.dttData)), _xlpm.tongTT,SUMPRODUCT((_xlpm.nganhData=$A19)*(_xlpm.dttData)*(_xlpm.ttdttData)), IF(_xlpm.tongDT=0,"-",_xlpm.tongTT/_xlpm.tongDT) ) ) )} -> - | G19: {=_xlfn.LET( _xlpm.colNganh,_xlfn.XMATCH("*ICB L1*",Sheet4!$1:$1,2), _xlpm.colLNST,_xlfn.XMATCH("*Lợi nhuận sau thuế*Q2*2026*",Sheet4!$1:$1,2), _xlpm.colTTLNST,_xlfn.XMATCH("*Tăng trưởng lợi nhuận sau thuế (YoY) (Quý*",Sheet4!$1:$1,2), _xlpm.nganhData,INDEX(Sheet4!$2:$1605,0,_xlpm.colNganh), _xlpm.lnstData,INDEX(Sheet4!$2:$1605,0,_xlpm.colLNST), _xlpm.ttlnstData,INDEX(Sheet4!$2:$1605,0,_xlpm.colTTLNST), _xlfn.LET( _xlpm.tongLNST,SUMPRODUCT((_xlpm.nganhData=$A19)*(_xlpm.lnstData)), _xlpm.tongTT,SUMPRODUCT((_xlpm.nganhData=$A19)*(_xlpm.lnstData)*(_xlpm.ttlnstData)), IF(_xlpm.tongLNST=0,"-",_xlpm.tongTT/_xlpm.tongLNST) ) )} -> -
A21: 📋 BẢNG KẾT QUẢ KINH DOANH CHI TIẾT CỔ PHIẾU
A22: STT | B22: Mã CP | C22: Tên công ty | D22: Sàn | E22: Vốn hóa thị trường (tỷ đồng) | F22: Ngành L1 | G22: Ngành L2 | H22: Ngành L4 | I22: DTT Q2/26 (tỷ đồng) | J22: DTT 6T/26 (tỷ đồng) | K22: TT DTT Q YoY | L22: TT DTT 6M YoY | M22: LNST Q2/26 (tỷ đồng) | N22: LNST 6T/26 (tỷ đồng) | O22: TT LNST Q YoY | P22: TT LNST 6M YoY | Q22: TT DTT QoQ | R22: TT LNST QoQ
A23: =Sheet4!A2 -> 1 | B23: =Sheet4!B2 -> AAA | C23: =Sheet4!C1 -> Tên công ty | D23: =Sheet4!D2 -> HOSE | E23: =Sheet4!AH2/1000000000 -> 2630.2014 | F23: =Sheet4!E2 -> Nguyên vật liệu | G23: =Sheet4!F2 -> Hóa chất | H23: =Sheet4!G2 -> Nhựa, cao su & sợi | I23: {=_xlfn.LET(_xlpm.colDTT,_xlfn.XMATCH("*Doanh thu thuần*Q2*2026*",Sheet4!$1:$1,2),_xlpm.colTNL,_xlfn.XMATCH("*Thu nhập lãi thuần*Quý: 2*2026*",Sheet4!$1:$1,2),_xlpm.maCP,ChiTietKQKD[[#This Row],[Mã CP]],_xlpm.nganhL1,ChiTietKQKD[[#This Row],[Ngành L1]],IF(_xlpm.nganhL1="Ngân hàng",_xlfn.LET(_xlpm.val,_xlfn.XLOOKUP(_xlpm.maCP,Sheet4!$B$2:$B$1605,INDEX(Sheet4!$2:$1605,0,_xlpm.colTNL)),IF(OR(_xlpm.val="",_xlpm.val=0),"",_xlpm.val/1000000000)),_xlfn.LET(_xlpm.val,_xlfn.XLOOKUP(_xlpm.maCP,Sheet4!$B$2:$B$1605,INDEX(Sheet4!$2:$1605,0,_xlpm.colDTT)),IF(OR(_xlpm.val="",_xlpm.val=0),"",_xlpm.val/1000000000))))} | J23: {=_xlfn.LET(_xlpm.colDTT,_xlfn.XMATCH("*Doanh thu thuần*6 tháng*2026*",Sheet4!$1:$1,2),_xlpm.colTNL,_xlfn.XMATCH("*Thu nhập lãi thuần*6 tháng*2026*",Sheet4!$1:$1,2),_xlpm.maCP,ChiTietKQKD[[#This Row],[Mã CP]],_xlpm.nganhL1,ChiTietKQKD[[#This Row],[Ngành L1]],IF(_xlpm.nganhL1="Ngân hàng",_xlfn.LET(_xlpm.val,_xlfn.XLOOKUP(_xlpm.maCP,Sheet4!$B$2:$B$1605,INDEX(Sheet4!$2:$1605,0,_xlpm.colTNL)),IF(OR(_xlpm.val="",_xlpm.val=0),"",_xlpm.val/1000000000)),_xlfn.LET(_xlpm.val,_xlfn.XLOOKUP(_xlpm.maCP,Sheet4!$B$2:$B$1605,INDEX(Sheet4!$2:$1605,0,_xlpm.colDTT)),IF(OR(_xlpm.val="",_xlpm.val=0),"",_xlpm.val/1000000000))))} | K23: {=IF(ChiTietKQKD[[#This Row],[Ngành L1]]="Ngân hàng",IF(AND(INDEX(Sheet4!$2:$1605,MATCH(ChiTietKQKD[[#This Row],[Mã CP]],Sheet4!$B$2:$B$1605,0),_xlfn.XMATCH("*Thu nhập lãi thuần*Quý: 2*2026*",Sheet4!$1:$1,2))<>0,INDEX(Sheet4!$2:$1605,MATCH(ChiTietKQKD[[#This Row],[Mã CP]],Sheet4!$B$2:$B$1605,0),_xlfn.XMATCH("*Thu nhập lãi thuần*Q2*2025*",Sheet4!$1:$1,2))<>0),INDEX(Sheet4!$2:$1605,MATCH(ChiTietKQKD[[#This Row],[Mã CP]],Sheet4!$B$2:$B$1605,0),_xlfn.XMATCH("*Thu nhập lãi thuần*Quý: 2*2026*",Sheet4!$1:$1,2))/INDEX(Sheet4!$2:$1605,MATCH(ChiTietKQKD[[#This Row],[Mã CP]],Sheet4!$B$2:$B$1605,0),_xlfn.XMATCH("*Thu nhập lãi thuần*Q2*2025*",Sheet4!$1:$1,2))-1,""),IFERROR(INDEX(Sheet4!$2:$1605,MATCH(ChiTietKQKD[[#This Row],[Mã CP]],Sheet4!$B$2:$B$1605,0),_xlfn.XMATCH("*Tăng trưởng doanh thu thuần (YoY) (Quý*",Sheet4!$1:$1,2)),""))} -> 0 | L23: {=IF(ChiTietKQKD[[#This Row],[Ngành L1]]="Ngân hàng",IF(AND(INDEX(Sheet4!$2:$1605,MATCH(ChiTietKQKD[[#This Row],[Mã CP]],Sheet4!$B$2:$B$1605,0),_xlfn.XMATCH("*Thu nhập lãi thuần*6 tháng*2026*",Sheet4!$1:$1,2))<>0,INDEX(Sheet4!$2:$1605,MATCH(ChiTietKQKD[[#This Row],[Mã CP]],Sheet4!$B$2:$B$1605,0),_xlfn.XMATCH("*Thu nhập lãi thuần*6 tháng*2025*",Sheet4!$1:$1,2))<>0),INDEX(Sheet4!$2:$1605,MATCH(ChiTietKQKD[[#This Row],[Mã CP]],Sheet4!$B$2:$B$1605,0),_xlfn.XMATCH("*Thu nhập lãi thuần*6 tháng*2026*",Sheet4!$1:$1,2))/INDEX(Sheet4!$2:$1605,MATCH(ChiTietKQKD[[#This Row],[Mã CP]],Sheet4!$B$2:$B$1605,0),_xlfn.XMATCH("*Thu nhập lãi thuần*6 tháng*2025*",Sheet4!$1:$1,2))-1,""),IFERROR(INDEX(Sheet4!$2:$1605,MATCH(ChiTietKQKD[[#This Row],[Mã CP]],Sheet4!$B$2:$B$1605,0),_xlfn.XMATCH("*Tăng trưởng doanh thu thuần (YoY) (6M)*",Sheet4!$1:$1,2)),""))} -> 0 | M23: {=_xlfn.LET(_xlpm.val,IFERROR(INDEX(Sheet4!$2:$1605,MATCH(ChiTietKQKD[[#This Row],[Mã CP]],Sheet4!$B$2:$B$1605,0),_xlfn.XMATCH("*Lợi nhuận sau thuế*Q2*2026*",Sheet4!$1:$1,2)),0),IF(OR(_xlpm.val="",_xlpm.val=0),"",_xlpm.val/1000000000))} | N23: {=_xlfn.LET(_xlpm.val,IFERROR(INDEX(Sheet4!$2:$1605,MATCH(ChiTietKQKD[[#This Row],[Mã CP]],Sheet4!$B$2:$B$1605,0),_xlfn.XMATCH("*Lợi nhuận sau thuế*6 tháng*2026*",Sheet4!$1:$1,2)),0),IF(OR(_xlpm.val="",_xlpm.val=0),"",_xlpm.val/1000000000))} | O23: {=IFERROR(INDEX(Sheet4!$2:$1605,MATCH(ChiTietKQKD[[#This Row],[Mã CP]],Sheet4!$B$2:$B$1605,0),_xlfn.XMATCH("*Tăng trưởng lợi nhuận sau thuế (YoY) (Quý*",Sheet4!$1:$1,2)),"")} -> 0 | P23: {=IFERROR(INDEX(Sheet4!$2:$1605,MATCH(ChiTietKQKD[[#This Row],[Mã CP]],Sheet4!$B$2:$B$1605,0),_xlfn.XMATCH("*Tăng trưởng lợi nhuận sau thuế (YoY) (6M)*",Sheet4!$1:$1,2)),"")} -> 0 | Q23: {=IFERROR(INDEX(Sheet4!$2:$1605,MATCH(ChiTietKQKD[[#This Row],[Mã CP]],Sheet4!$B$2:$B$1605,0),_xlfn.XMATCH("*Tăng trưởng doanh thu thuần (QoQ)*",Sheet4!$1:$1,2)),"")} -> 0 | R23: {=IFERROR(INDEX(Sheet4!$2:$1605,MATCH(ChiTietKQKD[[#This Row],[Mã CP]],Sheet4!$B$2:$B$1605,0),_xlfn.XMATCH("*Tăng trưởng lợi nhuận sau thuế (QoQ)*",Sheet4!$1:$1,2)),"")} -> 0
A24: =Sheet4!A3 -> 2 | B24: =Sheet4!B3 -> AAM | C24: =Sheet4!C2 -> An Phát Bioplastics | D24: =Sheet4!D3 -> HOSE | E24: =Sheet4!AH3/1000000000 -> 68.455242 | F24: =Sheet4!E3 -> Hàng Tiêu dùng | G24: =Sheet4!F3 -> Thực phẩm và đồ uống | H24: =Sheet4!G3 -> Nuôi trồng nông & hải sản | I24: {=_xlfn.LET(_xlpm.colDTT,_xlfn.XMATCH("*Doanh thu thuần*Q2*2026*",Sheet4!$1:$1,2),_xlpm.colTNL,_xlfn.XMATCH("*Thu nhập lãi thuần*Quý: 2*2026*",Sheet4!$1:$1,2),_xlpm.maCP,ChiTietKQKD[[#This Row],[Mã CP]],_xlpm.nganhL1,ChiTietKQKD[[#This Row],[Ngành L1]],IF(_xlpm.nganhL1="Ngân hàng",_xlfn.LET(_xlpm.val,_xlfn.XLOOKUP(_xlpm.maCP,Sheet4!$B$2:$B$1605,INDEX(Sheet4!$2:$1605,0,_xlpm.colTNL)),IF(OR(_xlpm.val="",_xlpm.val=0),"",_xlpm.val/1000000000)),_xlfn.LET(_xlpm.val,_xlfn.XLOOKUP(_xlpm.maCP,Sheet4!$B$2:$B$1605,INDEX(Sheet4!$2:$1605,0,_xlpm.colDTT)),IF(OR(_xlpm.val="",_xlpm.val=0),"",_xlpm.val/1000000000))))} -> 16.795302 | J24: {=_xlfn.LET(_xlpm.colDTT,_xlfn.XMATCH("*Doanh thu thuần*6 tháng*2026*",Sheet4!$1:$1,2),_xlpm.colTNL,_xlfn.XMATCH("*Thu nhập lãi thuần*6 tháng*2026*",Sheet4!$1:$1,2),_xlpm.maCP,ChiTietKQKD[[#This Row],[Mã CP]],_xlpm.nganhL1,ChiTietKQKD[[#This Row],[Ngành L1]],IF(_xlpm.nganhL1="Ngân hàng",_xlfn.LET(_xlpm.val,_xlfn.XLOOKUP(_xlpm.maCP,Sheet4!$B$2:$B$1605,INDEX(Sheet4!$2:$1605,0,_xlpm.colTNL)),IF(OR(_xlpm.val="",_xlpm.val=0),"",_xlpm.val/1000000000)),_xlfn.LET(_xlpm.val,_xlfn.XLOOKUP(_xlpm.maCP,Sheet4!$B$2:$B$1605,INDEX(Sheet4!$2:$1605,0,_xlpm.colDTT)),IF(OR(_xlpm.val="",_xlpm.val=0),"",_xlpm.val/1000000000))))} -> 50.239307 | K24: {=IF(ChiTietKQKD[[#This Row],[Ngành L1]]="Ngân hàng",IF(AND(INDEX(Sheet4!$2:$1605,MATCH(ChiTietKQKD[[#This Row],[Mã CP]],Sheet4!$B$2:$B$1605,0),_xlfn.XMATCH("*Thu nhập lãi thuần*Quý: 2*2026*",Sheet4!$1:$1,2))<>0,INDEX(Sheet4!$2:$1605,MATCH(ChiTietKQKD[[#This Row],[Mã CP]],Sheet4!$B$2:$B$1605,0),_xlfn.XMATCH("*Thu nhập lãi thuần*Q2*2025*",Sheet4!$1:$1,2))<>0),INDEX(Sheet4!$2:$1605,MATCH(ChiTietKQKD[[#This Row],[Mã CP]],Sheet4!$B$2:$B$1605,0),_xlfn.XMATCH("*Thu nhập lãi thuần*Quý: 2*2026*",Sheet4!$1:$1,2))/INDEX(Sheet4!$2:$1605,MATCH(ChiTietKQKD[[#This Row],[Mã CP]],Sheet4!$B$2:$B$1605,0),_xlfn.XMATCH("*Thu nhập lãi thuần*Q2*2025*",Sheet4!$1:$1,2))-1,""),IFERROR(INDEX(Sheet4!$2:$1605,MATCH(ChiTietKQKD[[#This Row],[Mã CP]],Sheet4!$B$2:$B$1605,0),_xlfn.XMATCH("*Tăng trưởng doanh thu thuần (YoY) (Quý*",Sheet4!$1:$1,2)),""))} -> -0.7389 | L24: {=IF(ChiTietKQKD[[#This Row],[Ngành L1]]="Ngân hàng",IF(AND(INDEX(Sheet4!$2:$1605,MATCH(ChiTietKQKD[[#This Row],[Mã CP]],Sheet4!$B$2:$B$1605,0),_xlfn.XMATCH("*Thu nhập lãi thuần*6 tháng*2026*",Sheet4!$1:$1,2))<>0,INDEX(Sheet4!$2:$1605,MATCH(ChiTietKQKD[[#This Row],[Mã CP]],Sheet4!$B$2:$B$1605,0),_xlfn.XMATCH("*Thu nhập lãi thuần*6 tháng*2025*",Sheet4!$1:$1,2))<>0),INDEX(Sheet4!$2:$1605,MATCH(ChiTietKQKD[[#This Row],[Mã CP]],Sheet4!$B$2:$B$1605,0),_xlfn.XMATCH("*Thu nhập lãi thuần*6 tháng*2026*",Sheet4!$1:$1,2))/INDEX(Sheet4!$2:$1605,MATCH(ChiTietKQKD[[#This Row],[Mã CP]],Sheet4!$B$2:$B$1605,0),_xlfn.XMATCH("*Thu nhập lãi thuần*6 tháng*2025*",Sheet4!$1:$1,2))-1,""),IFERROR(INDEX(Sheet4!$2:$1605,MATCH(ChiTietKQKD[[#This Row],[Mã CP]],Sheet4!$B$2:$B$1605,0),_xlfn.XMATCH("*Tăng trưởng doanh thu thuần (YoY) (6M)*",Sheet4!$1:$1,2)),""))} -> -0.5767 | M24: {=_xlfn.LET(_xlpm.val,IFERROR(INDEX(Sheet4!$2:$1605,MATCH(ChiTietKQKD[[#This Row],[Mã CP]],Sheet4!$B$2:$B$1605,0),_xlfn.XMATCH("*Lợi nhuận sau thuế*Q2*2026*",Sheet4!$1:$1,2)),0),IF(OR(_xlpm.val="",_xlpm.val=0),"",_xlpm.val/1000000000))} -> 3.3907519 | N24: {=_xlfn.LET(_xlpm.val,IFERROR(INDEX(Sheet4!$2:$1605,MATCH(ChiTietKQKD[[#This Row],[Mã CP]],Sheet4!$B$2:$B$1605,0),_xlfn.XMATCH("*Lợi nhuận sau thuế*6 tháng*2026*",Sheet4!$1:$1,2)),0),IF(OR(_xlpm.val="",_xlpm.val=0),"",_xlpm.val/1000000000))} -> 5.7783557 | O24: {=IFERROR(INDEX(Sheet4!$2:$1605,MATCH(ChiTietKQKD[[#This Row],[Mã CP]],Sheet4!$B$2:$B$1605,0),_xlfn.XMATCH("*Tăng trưởng lợi nhuận sau thuế (YoY) (Quý*",Sheet4!$1:$1,2)),"")} -> 2.0053 | P24: {=IFERROR(INDEX(Sheet4!$2:$1605,MATCH(ChiTietKQKD[[#This Row],[Mã CP]],Sheet4!$B$2:$B$1605,0),_xlfn.XMATCH("*Tăng trưởng lợi nhuận sau thuế (YoY) (6M)*",Sheet4!$1:$1,2)),"")} -> 1.4728 | Q24: {=IFERROR(INDEX(Sheet4!$2:$1605,MATCH(ChiTietKQKD[[#This Row],[Mã CP]],Sheet4!$B$2:$B$1605,0),_xlfn.XMATCH("*Tăng trưởng doanh thu thuần (QoQ)*",Sheet4!$1:$1,2)),"")} -> -0.4978 | R24: {=IFERROR(INDEX(Sheet4!$2:$1605,MATCH(ChiTietKQKD[[#This Row],[Mã CP]],Sheet4!$B$2:$B$1605,0),_xlfn.XMATCH("*Tăng trưởng lợi nhuận sau thuế (QoQ)*",Sheet4!$1:$1,2)),"")} -> 0.4201
A25: =Sheet4!A4 -> 3 | B25: =Sheet4!B4 -> AAN | C25: =Sheet4!C3 -> Thủy sản Mekong | D25: =Sheet4!D4 -> HOSE | E25: =Sheet4!AH4/1000000000 -> 1388.4968 | F25: =Sheet4!E4 -> Hàng Tiêu dùng | G25: =Sheet4!F4 -> Thực phẩm và đồ uống | H25: =Sheet4!G4 -> Nuôi trồng nông & hải sản | I25: {=_xlfn.LET(_xlpm.colDTT,_xlfn.XMATCH("*Doanh thu thuần*Q2*2026*",Sheet4!$1:$1,2),_xlpm.colTNL,_xlfn.XMATCH("*Thu nhập lãi thuần*Quý: 2*2026*",Sheet4!$1:$1,2),_xlpm.maCP,ChiTietKQKD[[#This Row],[Mã CP]],_xlpm.nganhL1,ChiTietKQKD[[#This Row],[Ngành L1]],IF(_xlpm.nganhL1="Ngân hàng",_xlfn.LET(_xlpm.val,_xlfn.XLOOKUP(_xlpm.maCP,Sheet4!$B$2:$B$1605,INDEX(Sheet4!$2:$1605,0,_xlpm.colTNL)),IF(OR(_xlpm.val="",_xlpm.val=0),"",_xlpm.val/1000000000)),_xlfn.LET(_xlpm.val,_xlfn.XLOOKUP(_xlpm.maCP,Sheet4!$B$2:$B$1605,INDEX(Sheet4!$2:$1605,0,_xlpm.colDTT)),IF(OR(_xlpm.val="",_xlpm.val=0),"",_xlpm.val/1000000000))))} | J25: {=_xlfn.LET(_xlpm.colDTT,_xlfn.XMATCH("*Doanh thu thuần*6 tháng*2026*",Sheet4!$1:$1,2),_xlpm.colTNL,_xlfn.XMATCH("*Thu nhập lãi thuần*6 tháng*2026*",Sheet4!$1:$1,2),_xlpm.maCP,ChiTietKQKD[[#This Row],[Mã CP]],_xlpm.nganhL1,ChiTietKQKD[[#This Row],[Ngành L1]],IF(_xlpm.nganhL1="Ngân hàng",_xlfn.LET(_xlpm.val,_xlfn.XLOOKUP(_xlpm.maCP,Sheet4!$B$2:$B$1605,INDEX(Sheet4!$2:$1605,0,_xlpm.colTNL)),IF(OR(_xlpm.val="",_xlpm.val=0),"",_xlpm.val/1000000000)),_xlfn.LET(_xlpm.val,_xlfn.XLOOKUP(_xlpm.maCP,Sheet4!$B$2:$B$1605,INDEX(Sheet4!$2:$1605,0,_xlpm.colDTT)),IF(OR(_xlpm.val="",_xlpm.val=0),"",_xlpm.val/1000000000))))} | K25: {=IF(ChiTietKQKD[[#This Row],[Ngành L1]]="Ngân hàng",IF(AND(INDEX(Sheet4!$2:$1605,MATCH(ChiTietKQKD[[#This Row],[Mã CP]],Sheet4!$B$2:$B$1605,0),_xlfn.XMATCH("*Thu nhập lãi thuần*Quý: 2*2026*",Sheet4!$1:$1,2))<>0,INDEX(Sheet4!$2:$1605,MATCH(ChiTietKQKD[[#This Row],[Mã CP]],Sheet4!$B$2:$B$1605,0),_xlfn.XMATCH("*Thu nhập lãi thuần*Q2*2025*",Sheet4!$1:$1,2))<>0),INDEX(Sheet4!$2:$1605,MATCH(ChiTietKQKD[[#This Row],[Mã CP]],Sheet4!$B$2:$B$1605,0),_xlfn.XMATCH("*Thu nhập lãi thuần*Quý: 2*2026*",Sheet4!$1:$1,2))/INDEX(Sheet4!$2:$1605,MATCH(ChiTietKQKD[[#This Row],[Mã CP]],Sheet4!$B$2:$B$1605,0),_xlfn.XMATCH("*Thu nhập lãi thuần*Q2*2025*",Sheet4!$1:$1,2))-1,""),IFERROR(INDEX(Sheet4!$2:$1605,MATCH(ChiTietKQKD[[#This Row],[Mã CP]],Sheet4!$B$2:$B$1605,0),_xlfn.XMATCH("*Tăng trưởng doanh thu thuần (YoY) (Quý*",Sheet4!$1:$1,2)),""))} -> 0 | L25: {=IF(ChiTietKQKD[[#This Row],[Ngành L1]]="Ngân hàng",IF(AND(INDEX(Sheet4!$2:$1605,MATCH(ChiTietKQKD[[#This Row],[Mã CP]],Sheet4!$B$2:$B$1605,0),_xlfn.XMATCH("*Thu nhập lãi thuần*6 tháng*2026*",Sheet4!$1:$1,2))<>0,INDEX(Sheet4!$2:$1605,MATCH(ChiTietKQKD[[#This Row],[Mã CP]],Sheet4!$B$2:$B$1605,0),_xlfn.XMATCH("*Thu nhập lãi thuần*6 tháng*2025*",Sheet4!$1:$1,2))<>0),INDEX(Sheet4!$2:$1605,MATCH(ChiTietKQKD[[#This Row],[Mã CP]],Sheet4!$B$2:$B$1605,0),_xlfn.XMATCH("*Thu nhập lãi thuần*6 tháng*2026*",Sheet4!$1:$1,2))/INDEX(Sheet4!$2:$1605,MATCH(ChiTietKQKD[[#This Row],[Mã CP]],Sheet4!$B$2:$B$1605,0),_xlfn.XMATCH("*Thu nhập lãi thuần*6 tháng*2025*",Sheet4!$1:$1,2))-1,""),IFERROR(INDEX(Sheet4!$2:$1605,MATCH(ChiTietKQKD[[#This Row],[Mã CP]],Sheet4!$B$2:$B$1605,0),_xlfn.XMATCH("*Tăng trưởng doanh thu thuần (YoY) (6M)*",Sheet4!$1:$1,2)),""))} -> 0 | M25: {=_xlfn.LET(_xlpm.val,IFERROR(INDEX(Sheet4!$2:$1605,MATCH(ChiTietKQKD[[#This Row],[Mã CP]],Sheet4!$B$2:$B$1605,0),_xlfn.XMATCH("*Lợi nhuận sau thuế*Q2*2026*",Sheet4!$1:$1,2)),0),IF(OR(_xlpm.val="",_xlpm.val=0),"",_xlpm.val/1000000000))} | N25: {=_xlfn.LET(_xlpm.val,IFERROR(INDEX(Sheet4!$2:$1605,MATCH(ChiTietKQKD[[#This Row],[Mã CP]],Sheet4!$B$2:$B$1605,0),_xlfn.XMATCH("*Lợi nhuận sau thuế*6 tháng*2026*",Sheet4!$1:$1,2)),0),IF(OR(_xlpm.val="",_xlpm.val=0),"",_xlpm.val/1000000000))} | O25: {=IFERROR(INDEX(Sheet4!$2:$1605,MATCH(ChiTietKQKD[[#This Row],[Mã CP]],Sheet4!$B$2:$B$1605,0),_xlfn.XMATCH("*Tăng trưởng lợi nhuận sau thuế (YoY) (Quý*",Sheet4!$1:$1,2)),"")} -> 0 | P25: {=IFERROR(INDEX(Sheet4!$2:$1605,MATCH(ChiTietKQKD[[#This Row],[Mã CP]],Sheet4!$B$2:$B$1605,0),_xlfn.XMATCH("*Tăng trưởng lợi nhuận sau thuế (YoY) (6M)*",Sheet4!$1:$1,2)),"")} -> 0 | Q25: {=IFERROR(INDEX(Sheet4!$2:$1605,MATCH(ChiTietKQKD[[#This Row],[Mã CP]],Sheet4!$B$2:$B$1605,0),_xlfn.XMATCH("*Tăng trưởng doanh thu thuần (QoQ)*",Sheet4!$1:$1,2)),"")} -> 0 | R25: {=IFERROR(INDEX(Sheet4!$2:$1605,MATCH(ChiTietKQKD[[#This Row],[Mã CP]],Sheet4!$B$2:$B$1605,0),_xlfn.XMATCH("*Tăng trưởng lợi nhuận sau thuế (QoQ)*",Sheet4!$1:$1,2)),"")} -> 0
A26: =Sheet4!A5 -> 4 | B26: =Sheet4!B5 -> AAT | C26: =Sheet4!C4 -> Lương thực A An | D26: =Sheet4!D5 -> HOSE | E26: =Sheet4!AH5/1000000000 -> 182.71329 | F26: =Sheet4!E5 -> Hàng Tiêu dùng | G26: =Sheet4!F5 -> Hàng cá nhân & Gia dụng | H26: =Sheet4!G5 -> Hàng May mặc | I26: {=_xlfn.LET(_xlpm.colDTT,_xlfn.XMATCH("*Doanh thu thuần*Q2*2026*",Sheet4!$1:$1,2),_xlpm.colTNL,_xlfn.XMATCH("*Thu nhập lãi thuần*Quý: 2*2026*",Sheet4!$1:$1,2),_xlpm.maCP,ChiTietKQKD[[#This Row],[Mã CP]],_xlpm.nganhL1,ChiTietKQKD[[#This Row],[Ngành L1]],IF(_xlpm.nganhL1="Ngân hàng",_xlfn.LET(_xlpm.val,_xlfn.XLOOKUP(_xlpm.maCP,Sheet4!$B$2:$B$1605,INDEX(Sheet4!$2:$1605,0,_xlpm.colTNL)),IF(OR(_xlpm.val="",_xlpm.val=0),"",_xlpm.val/1000000000)),_xlfn.LET(_xlpm.val,_xlfn.XLOOKUP(_xlpm.maCP,Sheet4!$B$2:$B$1605,INDEX(Sheet4!$2:$1605,0,_xlpm.colDTT)),IF(OR(_xlpm.val="",_xlpm.val=0),"",_xlpm.val/1000000000))))} | J26: {=_xlfn.LET(_xlpm.colDTT,_xlfn.XMATCH("*Doanh thu thuần*6 tháng*2026*",Sheet4!$1:$1,2),_xlpm.colTNL,_xlfn.XMATCH("*Thu nhập lãi thuần*6 tháng*2026*",Sheet4!$1:$1,2),_xlpm.maCP,ChiTietKQKD[[#This Row],[Mã CP]],_xlpm.nganhL1,ChiTietKQKD[[#This Row],[Ngành L1]],IF(_xlpm.nganhL1="Ngân hàng",_xlfn.LET(_xlpm.val,_xlfn.XLOOKUP(_xlpm.maCP,Sheet4!$B$2:$B$1605,INDEX(Sheet4!$2:$1605,0,_xlpm.colTNL)),IF(OR(_xlpm.val="",_xlpm.val=0),"",_xlpm.val/1000000000)),_xlfn.LET(_xlpm.val,_xlfn.XLOOKUP(_xlpm.maCP,Sheet4!$B$2:$B$1605,INDEX(Sheet4!$2:$1605,0,_xlpm.colDTT)),IF(OR(_xlpm.val="",_xlpm.val=0),"",_xlpm.val/1000000000))))} | K26: {=IF(ChiTietKQKD[[#This Row],[Ngành L1]]="Ngân hàng",IF(AND(INDEX(Sheet4!$2:$1605,MATCH(ChiTietKQKD[[#This Row],[Mã CP]],Sheet4!$B$2:$B$1605,0),_xlfn.XMATCH("*Thu nhập lãi thuần*Quý: 2*2026*",Sheet4!$1:$1,2))<>0,INDEX(Sheet4!$2:$1605,MATCH(ChiTietKQKD[[#This Row],[Mã CP]],Sheet4!$B$2:$B$1605,0),_xlfn.XMATCH("*Thu nhập lãi thuần*Q2*2025*",Sheet4!$1:$1,2))<>0),INDEX(Sheet4!$2:$1605,MATCH(ChiTietKQKD[[#This Row],[Mã CP]],Sheet4!$B$2:$B$1605,0),_xlfn.XMATCH("*Thu nhập lãi thuần*Quý: 2*2026*",Sheet4!$1:$1,2))/INDEX(Sheet4!$2:$1605,MATCH(ChiTietKQKD[[#This Row],[Mã CP]],Sheet4!$B$2:$B$1605,0),_xlfn.XMATCH("*Thu nhập lãi thuần*Q2*2025*",Sheet4!$1:$1,2))-1,""),IFERROR(INDEX(Sheet4!$2:$1605,MATCH(ChiTietKQKD[[#This Row],[Mã CP]],Sheet4!$B$2:$B$1605,0),_xlfn.XMATCH("*Tăng trưởng doanh thu thuần (YoY) (Quý*",Sheet4!$1:$1,2)),""))} -> 0 | L26: {=IF(ChiTietKQKD[[#This Row],[Ngành L1]]="Ngân hàng",IF(AND(INDEX(Sheet4!$2:$1605,MATCH(ChiTietKQKD[[#This Row],[Mã CP]],Sheet4!$B$2:$B$1605,0),_xlfn.XMATCH("*Thu nhập lãi thuần*6 tháng*2026*",Sheet4!$1:$1,2))<>0,INDEX(Sheet4!$2:$1605,MATCH(ChiTietKQKD[[#This Row],[Mã CP]],Sheet4!$B$2:$B$1605,0),_xlfn.XMATCH("*Thu nhập lãi thuần*6 tháng*2025*",Sheet4!$1:$1,2))<>0),INDEX(Sheet4!$2:$1605,MATCH(ChiTietKQKD[[#This Row],[Mã CP]],Sheet4!$B$2:$B$1605,0),_xlfn.XMATCH("*Thu nhập lãi thuần*6 tháng*2026*",Sheet4!$1:$1,2))/INDEX(Sheet4!$2:$1605,MATCH(ChiTietKQKD[[#This Row],[Mã CP]],Sheet4!$B$2:$B$1605,0),_xlfn.XMATCH("*Thu nhập lãi thuần*6 tháng*2025*",Sheet4!$1:$1,2))-1,""),IFERROR(INDEX(Sheet4!$2:$1605,MATCH(ChiTietKQKD[[#This Row],[Mã CP]],Sheet4!$B$2:$B$1605,0),_xlfn.XMATCH("*Tăng trưởng doanh thu thuần (YoY) (6M)*",Sheet4!$1:$1,2)),""))} -> 0 | M26: {=_xlfn.LET(_xlpm.val,IFERROR(INDEX(Sheet4!$2:$1605,MATCH(ChiTietKQKD[[#This Row],[Mã CP]],Sheet4!$B$2:$B$1605,0),_xlfn.XMATCH("*Lợi nhuận sau thuế*Q2*2026*",Sheet4!$1:$1,2)),0),IF(OR(_xlpm.val="",_xlpm.val=0),"",_xlpm.val/1000000000))} | N26: {=_xlfn.LET(_xlpm.val,IFERROR(INDEX(Sheet4!$2:$1605,MATCH(ChiTietKQKD[[#This Row],[Mã CP]],Sheet4!$B$2:$B$1605,0),_xlfn.XMATCH("*Lợi nhuận sau thuế*6 tháng*2026*",Sheet4!$1:$1,2)),0),IF(OR(_xlpm.val="",_xlpm.val=0),"",_xlpm.val/1000000000))} | O26: {=IFERROR(INDEX(Sheet4!$2:$1605,MATCH(ChiTietKQKD[[#This Row],[Mã CP]],Sheet4!$B$2:$B$1605,0),_xlfn.XMATCH("*Tăng trưởng lợi nhuận sau thuế (YoY) (Quý*",Sheet4!$1:$1,2)),"")} -> 0 | P26: {=IFERROR(INDEX(Sheet4!$2:$1605,MATCH(ChiTietKQKD[[#This Row],[Mã CP]],Sheet4!$B$2:$B$1605,0),_xlfn.XMATCH("*Tăng trưởng lợi nhuận sau thuế (YoY) (6M)*",Sheet4!$1:$1,2)),"")} -> 0 | Q26: {=IFERROR(INDEX(Sheet4!$2:$1605,MATCH(ChiTietKQKD[[#This Row],[Mã CP]],Sheet4!$B$2:$B$1605,0),_xlfn.XMATCH("*Tăng trưởng doanh thu thuần (QoQ)*",Sheet4!$1:$1,2)),"")} -> 0 | R26: {=IFERROR(INDEX(Sheet4!$2:$1605,MATCH(ChiTietKQKD[[#This Row],[Mã CP]],Sheet4!$B$2:$B$1605,0),_xlfn.XMATCH("*Tăng trưởng lợi nhuận sau thuế (QoQ)*",Sheet4!$1:$1,2)),"")} -> 0
